Workbook

Sheet All_Unique_Types
A1: Notes | B1: Assigned manually | C1: Cross check with combined_system.data | D1: Cross check with combined_system.data | E1: Same as B | F1: Except Li (3rd row) everything else is by matching the corresponding sheets for columns F and G | H1: Comment # | I1: Add comments | K1: Compile all the UNIQUE PAIR DATA from all the Excel Sheets | U1: Compile all the UNIQUE BOND DATA from all the Excel Sheets | AA1: Concatenate | AC1: Copy Bond Coeff Data from combined_data.data | AE1: k_lmp = 0.00119502868*k_gmx | AF1: r0 (lmp) = 10*r0(gmx) | AM1: Compile all the UNIQUE ANGLE DATA from all the Excel Sheets | AT1: Combined | AV1: Copy Angle Coeff Data from combined_data.data | AX1: k_lmp = 0.119502868*k_gmx | AY1: theta0 (lmp) = theta0(gmx) | BE1: Compile all the UNIQUE DIHEDRAL DATA from all the Excel Sheets | BQ1: Copy Dihed Coeff Data from combined_data.data | BS1: k1 (lmp) = 0.239*(-2c1 (gmx) -1.5*C3 (gmx)) | BT1: k2 (lmp) = 0.239*(c0 (gmx) + c1 (gmx) + c3 (gmx)) | BU1: k3 (lmp) = -0.5*c3 (gmx) | BV1: k4 (lmp) = -0.25*C4 (gmx)
A2: # | B2: NewID | C2: type | D2: mass | E2: NewType_ID | F2: LJ epsilon (lmp) | G2: Lj sigma (lmp) | H2: # | I2: Comments | K2: # Pair_Coeffs | L2: NewType_ID-1 | M2: NewType_ID-2 | N2: epsilon (kj/mol) | O2: sigma (Angstrom) | P2: cut-off rc (Angstrom) | Q2: #Comments | U2: # | V2: r0 (gmx,nm) | W2: k0 (gmx, kcal/mol) | X2: Type-1 | Y2: Type-2 | Z2: Type1-Type2 | AB2: # Bond Coeffs | AC2: New_BondType_ID | AD2: k_(lmp) | AE2: r0_(lmp) | AF2: # | AG2: Comment | AM2: # | AN2: theta_0 | AO2: k | AP2: type-1 | AQ2: type-2 | AR2: type-3 | AS2: #Combined | AU2: # Angle Coeffs | AV2: New_AngleType_ID | AW2: k_(lmp) | AX2: theta0_(lmp) | AY2: # | AZ2: Comments | BE2: # | BF2: =PEO_LMP_GMX_UniqueMap!BV2&" (gmx)" -> c0 (gmx) | BG2: =PEO_LMP_GMX_UniqueMap!BW2&" (gmx)" -> c1 (gmx) | BH2: =PEO_LMP_GMX_UniqueMap!BX2&" (gmx)" -> c2 (gmx) | BI2: =PEO_LMP_GMX_UniqueMap!BY2&" (gmx)" -> c3 (gmx) | BJ2: =PEO_LMP_GMX_UniqueMap!BZ2&" (gmx)" -> c4 (gmx) | BK2: =PEO_LMP_GMX_UniqueMap!CA2&" (gmx)" -> c5 (gmx) | BL2: sum_c (gmx) | BM2: type | BP2: # Dihedral Coeffs | BQ2: New_DihedType_ID | BR2: k1_(lmp) | BS2: k2_(lmp) | BT2: k3_(lmp) | BU2: k4_(lmp) | BV2: # | BW2: Comments
B3: 1 | C3: Li | D3: 6.941 | E3: =B3 -> 1 | F3: 2.15105 | G3: 2.49 | H3: # | I3: Li-LI/Surface (Ebadi Electrochimica Acta, 234, 43-51) | K3: pair_coeff | L3: =E3 -> 1 | M3: =E3 -> 1 | N3: =F3 -> 2.15105 | O3: =G3 -> 2.49 | P3: =2.5*O3 -> 6.225 | Q3: =H3&" "&I3 -> # Li-LI/Surface (Ebadi Electrochimica Acta, 234, 43-51) | U3: 1 | V3: =PEO_LMP_GMX_UniqueMap!AB3 -> 0.141 | W3: =PEO_LMP_GMX_UniqueMap!AC3 -> 267776 | X3: =PEO_LMP_GMX_UniqueMap!AD3 -> O1P | Y3: =PEO_LMP_GMX_UniqueMap!AE3 -> C1P | Z3: =X3&"-"&Y3 -> O1P-C1P | AB3: bond_coeff | AC3: 1 | AD3: {=_xlfn.XLOOKUP(AG3,$Z$3:$Z$22,ROUND(0.00119502868*$W$3:$W$22,2))} -> 268 | AE3: {=_xlfn.XLOOKUP(AG3,$Z$3:$Z$22,ROUND(10*$V$3:$V$22,4))} -> 1.529 | AF3: # | AG3: C1P-C1P | AM3: 1 | AN3: =PEO_LMP_GMX_UniqueMap!AU3 -> 109.5 | AO3: =PEO_LMP_GMX_UniqueMap!AV3 -> 502.08 | AP3: =PEO_LMP_GMX_UniqueMap!AW3 -> C1P | AQ3: =PEO_LMP_GMX_UniqueMap!AX3 -> O1P | AR3: =PEO_LMP_GMX_UniqueMap!AY3 -> C1P | AS3: =AP3&"-"&AQ3&"-"&AR3 -> C1P-O1P-C1P | AU3: angle_coeff | AV3: 1 | AW3: {=_xlfn.XLOOKUP(AZ3,$AS$3:$AS$37,ROUND(0.119502868*$AO$3:$AO$37,3))} -> 37.5 | AX3: {=_xlfn.XLOOKUP(AZ3,$AS$3:$AS$37,ROUND($AN$3:$AN$37,3))} -> 110.7 | AY3: # | AZ3: C1P-C1P-HP | BE3: 1 | BF3: =PEO_LMP_GMX_UniqueMap!BV3+0.001 -> 1.716 | BG3: =PEO_LMP_GMX_UniqueMap!BW3 -> 2.845 | BH3: =PEO_LMP_GMX_UniqueMap!BX3 -> 1.046 | BI3: =PEO_LMP_GMX_UniqueMap!BY3 -> -5.607 | BJ3: =PEO_LMP_GMX_UniqueMap!BZ3 -> 0 | BK3: =PEO_LMP_GMX_UniqueMap!CA3 -> 0 | BL3: =SUM(BF3:BK3) -> 0 | BM3: =PEO_LMP_GMX_UniqueMap!CB3&"-"&PEO_LMP_GMX_UniqueMap!CC3&"-"&PEO_LMP_GMX_UniqueMap!CD3&"-"&PEO_LMP_GMX_UniqueMap!CE3 -> C1P-C1P-O1P-C1P | BP3: dihedral_coeff | BQ3: 1 | BR3: {=ROUND(0.239005736*(-2*_xlfn.XLOOKUP(BW3,$BM$3:$BM$54,ROUND($BG$3:$BG$54,5)) - 1.5*_xlfn.XLOOKUP(BW3,$BM$3:$BM$54,ROUND($BI$3:$BI$54,5))),3)} -> 0.65 | BS3: {=ROUND(0.239005736*(_xlfn.XLOOKUP(BW3,$BM$3:$BM$54,ROUND($BF$3:$BF$54,5)) + _xlfn.XLOOKUP(BW3,$BM$3:$BM$54,ROUND($BG$3:$BG$54,5)) + _xlfn.XLOOKUP(BW3,$BM$3:$BM$54,ROUND($BI$3:$BI$54,5))),3)} -> -0.25 | BT3: {=ROUND(0.239005736*(-0.5*_xlfn.XLOOKUP(BW3,$BM$3:$BM$54,ROUND($BI$3:$BI$54,5))),3)} -> 0.67 | BU3: {=ROUND(0.239005736*(-0.25*_xlfn.XLOOKUP(BW3,$BM$3:$BM$54,ROUND($BJ$3:$BJ$54,5))),3)} -> 0 | BV3: # | BW3: C1P-C1P-O1P-C1P
B4: =B3+1 -> 2 | C4: =PEO_LMP_GMX_UniqueMap!N3 -> C1P | D4: =PEO_LMP_GMX_UniqueMap!M3 -> 12.011 | E4: =B4 -> 2 | F4: =PEO_LMP_GMX_UniqueMap!J3 -> 0.066 | G4: =PEO_LMP_GMX_UniqueMap!K3 -> 3.5 | H4: # | I4: C-EO/SEI | K4: pair_coeff | L4: =E4 -> 2 | M4: =E4 -> 2 | N4: =F4 -> 0.066 | O4: =G4 -> 3.5 | P4: =2.5*O4 -> 8.75 | Q4: =H4&" "&I4 -> # C-EO/SEI | U4: =U3+1 -> 2 | V4: =PEO_LMP_GMX_UniqueMap!AB4 -> 0.1529 | W4: =PEO_LMP_GMX_UniqueMap!AC4 -> 224262.4 | X4: =PEO_LMP_GMX_UniqueMap!AD4 -> C1P | Y4: =PEO_LMP_GMX_UniqueMap!AE4 -> C1P | Z4: =X4&"-"&Y4 -> C1P-C1P | AB4: bond_coeff | AC4: 2 | AD4: {=_xlfn.XLOOKUP(AG4,$Z$3:$Z$22,ROUND(0.00119502868*$W$3:$W$22,2))} -> 340 | AE4: {=_xlfn.XLOOKUP(AG4,$Z$3:$Z$22,ROUND(10*$V$3:$V$22,4))} -> 1.09 | AF4: # | AG4: HP-C1P | AM4: =AM3+1 -> 2 | AN4: =PEO_LMP_GMX_UniqueMap!AU4 -> 109.5 | AO4: =PEO_LMP_GMX_UniqueMap!AV4 -> 418.4 | AP4: =PEO_LMP_GMX_UniqueMap!AW4 -> O1P | AQ4: =PEO_LMP_GMX_UniqueMap!AX4 -> C1P | AR4: =PEO_LMP_GMX_UniqueMap!AY4 -> C1P | AS4: =AP4&"-"&AQ4&"-"&AR4 -> O1P-C1P-C1P | AU4: angle_coeff | AV4: 2 | AW4: {=_xlfn.XLOOKUP(AZ4,$AS$3:$AS$37,ROUND(0.119502868*$AO$3:$AO$37,3))} -> 50 | AX4: {=_xlfn.XLOOKUP(AZ4,$AS$3:$AS$37,ROUND($AN$3:$AN$37,3))} -> 109.5 | AY4: # | AZ4: O1P-C1P-C1P | BE4: =BE3+1 -> 2 | BF4: =PEO_LMP_GMX_UniqueMap!BV4-0.001 -> 0.627 | BG4: =PEO_LMP_GMX_UniqueMap!BW4 -> 1.883 | BH4: =PEO_LMP_GMX_UniqueMap!BX4 -> 0 | BI4: =PEO_LMP_GMX_UniqueMap!BY4 -> -2.51 | BJ4: =PEO_LMP_GMX_UniqueMap!BZ4 -> 0 | BK4: =PEO_LMP_GMX_UniqueMap!CA4 -> 0 | BL4: =SUM(BF4:BK4) -> 0 | BM4: =PEO_LMP_GMX_UniqueMap!CB4&"-"&PEO_LMP_GMX_UniqueMap!CC4&"-"&PEO_LMP_GMX_UniqueMap!CD4&"-"&PEO_LMP_GMX_UniqueMap!CE4 -> HP-C1P-C1P-HP | BP4: dihedral_coeff | BQ4: 2 | BR4: {=ROUND(0.239005736*(-2*_xlfn.XLOOKUP(BW4,$BM$3:$BM$54,ROUND($BG$3:$BG$54,5)) - 1.5*_xlfn.XLOOKUP(BW4,$BM$3:$BM$54,ROUND($BI$3:$BI$54,5))),3)} -> 0 | BS4: {=ROUND(0.239005736*(_xlfn.XLOOKUP(BW4,$BM$3:$BM$54,ROUND($BF$3:$BF$54,5)) + _xlfn.XLOOKUP(BW4,$BM$3:$BM$54,ROUND($BG$3:$BG$54,5)) + _xlfn.XLOOKUP(BW4,$BM$3:$BM$54,ROUND($BI$3:$BI$54,5))),3)} -> 0 | BT4: {=ROUND(0.239005736*(-0.5*_xlfn.XLOOKUP(BW4,$BM$3:$BM$54,ROUND($BI$3:$BI$54,5))),3)} -> 0.3 | BU4: {=ROUND(0.239005736*(-0.25*_xlfn.XLOOKUP(BW4,$BM$3:$BM$54,ROUND($BJ$3:$BJ$54,5))),3)} -> 0 | BV4: # | BW4: HP-C1P-C1P-HP
B5: =B4+1 -> 3 | C5: =PEO_LMP_GMX_UniqueMap!N5 -> HP | D5: =PEO_LMP_GMX_UniqueMap!M5 -> 1.008 | E5: =B5 -> 3 | F5: =PEO_LMP_GMX_UniqueMap!J5 -> 0.03 | G5: =PEO_LMP_GMX_UniqueMap!K5 -> 2.5 | H5: # | I5: H-EO/SEI | K5: pair_coeff | L5: =E5 -> 3 | M5: =E5 -> 3 | N5: =F5 -> 0.03 | O5: =G5 -> 2.5 | P5: =2.5*O5 -> 6.25 | Q5: =H5&" "&I5 -> # H-EO/SEI | U5: =U4+1 -> 3 | V5: =PEO_LMP_GMX_UniqueMap!AB5 -> 0.109 | W5: =PEO_LMP_GMX_UniqueMap!AC5 -> 284512 | X5: =PEO_LMP_GMX_UniqueMap!AD5 -> HP | Y5: =PEO_LMP_GMX_UniqueMap!AE5 -> C1P | Z5: =X5&"-"&Y5 -> HP-C1P | AB5: bond_coeff | AC5: 3 | AD5: {=_xlfn.XLOOKUP(AG5,$Z$3:$Z$22,ROUND(0.00119502868*$W$3:$W$22,2))} -> 320 | AE5: {=_xlfn.XLOOKUP(AG5,$Z$3:$Z$22,ROUND(10*$V$3:$V$22,4))} -> 1.41 | AF5: # | AG5: O1P-C1P | AM5: =AM4+1 -> 3 | AN5: =PEO_LMP_GMX_UniqueMap!AU5 -> 109.5 | AO5: =PEO_LMP_GMX_UniqueMap!AV5 -> 292.88 | AP5: =PEO_LMP_GMX_UniqueMap!AW5 -> O1P | AQ5: =PEO_LMP_GMX_UniqueMap!AX5 -> C1P | AR5: =PEO_LMP_GMX_UniqueMap!AY5 -> HP | AS5: =AP5&"-"&AQ5&"-"&AR5 -> O1P-C1P-HP | AU5: angle_coeff | AV5: 3 | AW5: {=_xlfn.XLOOKUP(AZ5,$AS$3:$AS$37,ROUND(0.119502868*$AO$3:$AO$37,3))} -> 60 | AX5: {=_xlfn.XLOOKUP(AZ5,$AS$3:$AS$37,ROUND($AN$3:$AN$37,3))} -> 109.5 | AY5: # | AZ5: C1P-O1P-C1P | BE5: =BE4+1 -> 3 | BF5: =PEO_LMP_GMX_UniqueMap!BV5 -> 0.979 | BG5: =PEO_LMP_GMX_UniqueMap!BW5 -> 2.937 | BH5: =PEO_LMP_GMX_UniqueMap!BX5 -> 0 | BI5: =PEO_LMP_GMX_UniqueMap!BY5 -> -3.916 | BJ5: =PEO_LMP_GMX_UniqueMap!BZ5 -> 0 | BK5: =PEO_LMP_GMX_UniqueMap!CA5 -> 0 | BL5: =SUM(BF5:BK5) -> 0 | BM5: =PEO_LMP_GMX_UniqueMap!CB5&"-"&PEO_LMP_GMX_UniqueMap!CC5&"-"&PEO_LMP_GMX_UniqueMap!CD5&"-"&PEO_LMP_GMX_UniqueMap!CE5 -> HP-C1P-C1P-O1P | BP5: dihedral_coeff | BQ5: 3 | BR5: {=ROUND(0.239005736*(-2*_xlfn.XLOOKUP(BW5,$BM$3:$BM$54,ROUND($BG$3:$BG$54,5)) - 1.5*_xlfn.XLOOKUP(BW5,$BM$3:$BM$54,ROUND($BI$3:$BI$54,5))),3)} -> 0 | BS5: {=ROUND(0.239005736*(_xlfn.XLOOKUP(BW5,$BM$3:$BM$54,ROUND($BF$3:$BF$54,5)) + _xlfn.XLOOKUP(BW5,$BM$3:$BM$54,ROUND($BG$3:$BG$54,5)) + _xlfn.XLOOKUP(BW5,$BM$3:$BM$54,ROUND($BI$3:$BI$54,5))),3)} -> 0 | BT5: {=ROUND(0.239005736*(-0.5*_xlfn.XLOOKUP(BW5,$BM$3:$BM$54,ROUND($BI$3:$BI$54,5))),3)} -> 0.468 | BU5: {=ROUND(0.239005736*(-0.25*_xlfn.XLOOKUP(BW5,$BM$3:$BM$54,ROUND($BJ$3:$BJ$54,5))),3)} -> 0 | BV5: # | BW5: HP-C1P-C1P-O1P
B6: =B5+1 -> 4 | C6: =PEO_LMP_GMX_UniqueMap!N4 -> O1P | D6: =PEO_LMP_GMX_UniqueMap!M4 -> 15.999 | E6: =B6 -> 4 | F6: =PEO_LMP_GMX_UniqueMap!J4 -> 0.14 | G6: =PEO_LMP_GMX_UniqueMap!K4 -> 2.9 | H6: # | I6: O-EO/SEI | K6: pair_coeff | L6: =E6 -> 4 | M6: =E6 -> 4 | N6: =F6 -> 0.14 | O6: =G6 -> 2.9 | P6: =2.5*O6 -> 7.25 | Q6: =H6&" "&I6 -> # O-EO/SEI | U6: =U5+1 -> 4 | V6: =CO32M_LMP_GMX_UniqueMap!AB3 -> 0.1229 | W6: =CO32M_LMP_GMX_UniqueMap!AC3 -> 476976 | X6: =CO32M_LMP_GMX_UniqueMap!AD3 -> C1C | Y6: =CO32M_LMP_GMX_UniqueMap!AE3 -> O1C | Z6: =X6&"-"&Y6 -> C1C-O1C | AB6: bond_coeff | AC6: 4 | AD6: {=_xlfn.XLOOKUP(AG6,$Z$3:$Z$22,ROUND(0.00119502868*$W$3:$W$22,2))} -> 570 | AE6: {=_xlfn.XLOOKUP(AG6,$Z$3:$Z$22,ROUND(10*$V$3:$V$22,4))} -> 1.229 | AF6: # | AG6: C1C-O1C | AM6: =AM5+1 -> 4 | AN6: =PEO_LMP_GMX_UniqueMap!AU6 -> 110.7 | AO6: =PEO_LMP_GMX_UniqueMap!AV6 -> 313.8 | AP6: =PEO_LMP_GMX_UniqueMap!AW6 -> C1P | AQ6: =PEO_LMP_GMX_UniqueMap!AX6 -> C1P | AR6: =PEO_LMP_GMX_UniqueMap!AY6 -> HP | AS6: =AP6&"-"&AQ6&"-"&AR6 -> C1P-C1P-HP | AU6: angle_coeff | AV6: 4 | AW6: {=_xlfn.XLOOKUP(AZ6,$AS$3:$AS$37,ROUND(0.119502868*$AO$3:$AO$37,3))} -> 33 | AX6: {=_xlfn.XLOOKUP(AZ6,$AS$3:$AS$37,ROUND($AN$3:$AN$37,3))} -> 107.8 | AY6: # | AZ6: HP-C1P-HP | BE6: =BE5+1 -> 4 | BF6: =PEO_LMP_GMX_UniqueMap!BV6 -> 1.59 | BG6: =PEO_LMP_GMX_UniqueMap!BW6 -> 4.77 | BH6: =PEO_LMP_GMX_UniqueMap!BX6 -> 0 | BI6: =PEO_LMP_GMX_UniqueMap!BY6 -> -6.36 | BJ6: =PEO_LMP_GMX_UniqueMap!BZ6 -> 0 | BK6: =PEO_LMP_GMX_UniqueMap!CA6 -> 0 | BL6: =SUM(BF6:BK6) -> -8.8817842e-16 | BM6: =PEO_LMP_GMX_UniqueMap!CB6&"-"&PEO_LMP_GMX_UniqueMap!CC6&"-"&PEO_LMP_GMX_UniqueMap!CD6&"-"&PEO_LMP_GMX_UniqueMap!CE6 -> HP-C1P-O1P-C1P | BP6: dihedral_coeff | BQ6: 4 | BR6: {=ROUND(0.239005736*(-2*_xlfn.XLOOKUP(BW6,$BM$3:$BM$54,ROUND($BG$3:$BG$54,5)) - 1.5*_xlfn.XLOOKUP(BW6,$BM$3:$BM$54,ROUND($BI$3:$BI$54,5))),3)} -> 0 | BS6: {=ROUND(0.239005736*(_xlfn.XLOOKUP(BW6,$BM$3:$BM$54,ROUND($BF$3:$BF$54,5)) + _xlfn.XLOOKUP(BW6,$BM$3:$BM$54,ROUND($BG$3:$BG$54,5)) + _xlfn.XLOOKUP(BW6,$BM$3:$BM$54,ROUND($BI$3:$BI$54,5))),3)} -> 0 | BT6: {=ROUND(0.239005736*(-0.5*_xlfn.XLOOKUP(BW6,$BM$3:$BM$54,ROUND($BI$3:$BI$54,5))),3)} -> 0.76 | BU6: {=ROUND(0.239005736*(-0.25*_xlfn.XLOOKUP(BW6,$BM$3:$BM$54,ROUND($BJ$3:$BJ$54,5))),3)} -> 0 | BV6: # | BW6: HP-C1P-O1P-C1P
B7: =B6+1 -> 5 | C7: LP | D7: 6.941 | E7: =B7 -> 5 | F7: 0.4 | G7: 1.4 | H7: # | I7: Li-LP/SEI (Table1: https://pubs.acs.org/doi/10.1021/acs.jpcb.3c05591, Wu-Wick) | K7: pair_coeff | L7: =E7 -> 5 | M7: =E7 -> 5 | N7: =F7 -> 0.4 | O7: =G7 -> 1.4 | P7: =2.5*O7 -> 3.5 | Q7: =H7&" "&I7 -> # Li-LP/SEI (Table1: https://pubs.acs.org/doi/10.1021/acs.jpcb.3c05591, Wu-Wick) | U7: =U6+1 -> 5 | V7: =CO32M_LMP_GMX_UniqueMap!AB4 -> 0.1364 | W7: =CO32M_LMP_GMX_UniqueMap!AC4 -> 376560 | X7: =CO32M_LMP_GMX_UniqueMap!AD4 -> O2C | Y7: =CO32M_LMP_GMX_UniqueMap!AE4 -> C1C | Z7: =X7&"-"&Y7 -> O2C-C1C | AB7: bond_coeff | AC7: 5 | AD7: {=_xlfn.XLOOKUP(AG7,$Z$3:$Z$22,ROUND(0.00119502868*$W$3:$W$22,2))} -> 450 | AE7: {=_xlfn.XLOOKUP(AG7,$Z$3:$Z$22,ROUND(10*$V$3:$V$22,4))} -> 1.364 | AF7: # | AG7: O2C-C1C | AM7: =AM6+1 -> 5 | AN7: =PEO_LMP_GMX_UniqueMap!AU7 -> 107.8 | AO7: =PEO_LMP_GMX_UniqueMap!AV7 -> 276.144 | AP7: =PEO_LMP_GMX_UniqueMap!AW7 -> HP | AQ7: =PEO_LMP_GMX_UniqueMap!AX7 -> C1P | AR7: =PEO_LMP_GMX_UniqueMap!AY7 -> HP | AS7: =AP7&"-"&AQ7&"-"&AR7 -> HP-C1P-HP | AU7: angle_coeff | AV7: 5 | AW7: {=_xlfn.XLOOKUP(AZ7,$AS$3:$AS$37,ROUND(0.119502868*$AO$3:$AO$37,3))} -> 35 | AX7: {=_xlfn.XLOOKUP(AZ7,$AS$3:$AS$37,ROUND($AN$3:$AN$37,3))} -> 109.5 | AY7: # | AZ7: O1P-C1P-HP | BE7: =BE6+1 -> 5 | BF7: =PEO_LMP_GMX_UniqueMap!BV7 -> -1.151 | BG7: =PEO_LMP_GMX_UniqueMap!BW7 -> 1.151 | BH7: =PEO_LMP_GMX_UniqueMap!BX7 -> 0 | BI7: =PEO_LMP_GMX_UniqueMap!BY7 -> 0 | BJ7: =PEO_LMP_GMX_UniqueMap!BZ7 -> 0 | BK7: =PEO_LMP_GMX_UniqueMap!CA7 -> 0 | BL7: =SUM(BF7:BK7) -> 0 | BM7: =PEO_LMP_GMX_UniqueMap!CB7&"-"&PEO_LMP_GMX_UniqueMap!CC7&"-"&PEO_LMP_GMX_UniqueMap!CD7&"-"&PEO_LMP_GMX_UniqueMap!CE7 -> O1P-C1P-C1P-O1P | BP7: dihedral_coeff | BQ7: 5 | BR7: {=ROUND(0.239005736*(-2*_xlfn.XLOOKUP(BW7,$BM$3:$BM$54,ROUND($BG$3:$BG$54,5)) - 1.5*_xlfn.XLOOKUP(BW7,$BM$3:$BM$54,ROUND($BI$3:$BI$54,5))),3)} -> -0.55 | BS7: {=ROUND(0.239005736*(_xlfn.XLOOKUP(BW7,$BM$3:$BM$54,ROUND($BF$3:$BF$54,5)) + _xlfn.XLOOKUP(BW7,$BM$3:$BM$54,ROUND($BG$3:$BG$54,5)) + _xlfn.XLOOKUP(BW7,$BM$3:$BM$54,ROUND($BI$3:$BI$54,5))),3)} -> 0 | BT7: {=ROUND(0.239005736*(-0.5*_xlfn.XLOOKUP(BW7,$BM$3:$BM$54,ROUND($BI$3:$BI$54,5))),3)} -> 0 | BU7: {=ROUND(0.239005736*(-0.25*_xlfn.XLOOKUP(BW7,$BM$3:$BM$54,ROUND($BJ$3:$BJ$54,5))),3)} -> 0 | BV7: # | BW7: O1P-C1P-C1P-O1P
B8: =B7+1 -> 6 | C8: =CO32M_LMP_GMX_UniqueMap!N4 -> C1C | D8: =CO32M_LMP_GMX_UniqueMap!M4 -> 12.011 | E8: =B8 -> 6 | F8: =CO32M_LMP_GMX_UniqueMap!J4 -> 0.07 | G8: =CO32M_LMP_GMX_UniqueMap!K4 -> 3.55 | H8: # | I8: C1-COI/SEI | K8: pair_coeff | L8: =E8 -> 6 | M8: =E8 -> 6 | N8: =F8 -> 0.07 | O8: =G8 -> 3.55 | P8: =2.5*O8 -> 8.875 | Q8: =H8&" "&I8 -> # C1-COI/SEI | U8: =U7+1 -> 6 | V8: =MTFSI_LMP_GMX_UniqueMap!AB3 -> 0.109 | W8: =MTFSI_LMP_GMX_UniqueMap!AC3 -> 284512 | X8: =MTFSI_LMP_GMX_UniqueMap!AD3 -> C1MT | Y8: =MTFSI_LMP_GMX_UniqueMap!AE3 -> HMT | Z8: =X8&"-"&Y8 -> C1MT-HMT | AB8: bond_coeff | AC8: 6 | AD8: {=_xlfn.XLOOKUP(AG8,$Z$3:$Z$22,ROUND(0.00119502868*$W$3:$W$22,2))} -> 268 | AE8: {=_xlfn.XLOOKUP(AG8,$Z$3:$Z$22,ROUND(10*$V$3:$V$22,4))} -> 1.529 | AF8: # | AG8: C1MT-C1MT | AM8: =AM7+1 -> 6 | AN8: =CO32M_LMP_GMX_UniqueMap!AU3 -> 121 | AO8: =CO32M_LMP_GMX_UniqueMap!AV3 -> 669.44 | AP8: =CO32M_LMP_GMX_UniqueMap!AW3 -> O1C | AQ8: =CO32M_LMP_GMX_UniqueMap!AX3 -> C1C | AR8: =CO32M_LMP_GMX_UniqueMap!AY3 -> O2C | AS8: =AP8&"-"&AQ8&"-"&AR8 -> O1C-C1C-O2C | AU8: angle_coeff | AV8: 6 | AW8: {=_xlfn.XLOOKUP(AZ8,$AS$3:$AS$37,ROUND(0.119502868*$AO$3:$AO$37,3))} -> 80 | AX8: {=_xlfn.XLOOKUP(AZ8,$AS$3:$AS$37,ROUND($AN$3:$AN$37,3))} -> 121 | AY8: # | AZ8: O1C-C1C-O2C | BE8: =BE7+1 -> 6 | BF8: =MTFSI_LMP_GMX_UniqueMap!BV3 -> -0.209 | BG8: =MTFSI_LMP_GMX_UniqueMap!BW3 -> -0.628 | BH8: =MTFSI_LMP_GMX_UniqueMap!BX3 -> 0 | BI8: =MTFSI_LMP_GMX_UniqueMap!BY3 -> 0.837 | BJ8: =MTFSI_LMP_GMX_UniqueMap!BZ3 -> 0 | BK8: =MTFSI_LMP_GMX_UniqueMap!CA3 -> 0 | BL8: =SUM(BF8:BK8) -> 0 | BM8: =MTFSI_LMP_GMX_UniqueMap!CB3&"-"&MTFSI_LMP_GMX_UniqueMap!CC3&"-"&MTFSI_LMP_GMX_UniqueMap!CD3&"-"&MTFSI_LMP_GMX_UniqueMap!CE3 -> C2MT-C1MT-C1MT-HMT | BP8: dihedral_coeff | BQ8: 6 | BR8: =BR62 -> 1.3 | BS8: =BS62 -> -0.2 | BT8: =BT62 -> 0.2 | BU8: =BU62 -> 0 | BV8: # | BW8: C1MT-C1MT-C1MT-C1MT | BX8: From CCCC in butane
B9: =B8+1 -> 7 | C9: =CO32M_LMP_GMX_UniqueMap!N3 -> O1C | D9: =CO32M_LMP_GMX_UniqueMap!M3 -> 15.999 | E9: =B9 -> 7 | F9: =CO32M_LMP_GMX_UniqueMap!J3 -> 0.21 | G9: =CO32M_LMP_GMX_UniqueMap!K3 -> 2.96 | H9: # | I9: O1-COI/SEI | K9: pair_coeff | L9: =E9 -> 7 | M9: =E9 -> 7 | N9: =F9 -> 0.21 | O9: =G9 -> 2.96 | P9: =2.5*O9 -> 7.4 | Q9: =H9&" "&I9 -> # O1-COI/SEI | U9: =U8+1 -> 7 | V9: =MTFSI_LMP_GMX_UniqueMap!AB4 -> 0.1229 | W9: =MTFSI_LMP_GMX_UniqueMap!AC4 -> 476976 | X9: =MTFSI_LMP_GMX_UniqueMap!AD4 -> O2MT | Y9: =MTFSI_LMP_GMX_UniqueMap!AE4 -> C2MT | Z9: =X9&"-"&Y9 -> O2MT-C2MT | AB9: bond_coeff | AC9: 7 | AD9: =AD8 -> 268 | AE9: =AE8 -> 1.529 | AF9: # | AG9: C1V-C1MT | AH9: ="Same as "&AG8 -> Same as C1MT-C1MT | AM9: =AM8+1 -> 7 | AN9: =CO32M_LMP_GMX_UniqueMap!AU4 -> 118.18 | AO9: =CO32M_LMP_GMX_UniqueMap!AV4 -> 584.923 | AP9: =CO32M_LMP_GMX_UniqueMap!AW4 -> O2C | AQ9: =CO32M_LMP_GMX_UniqueMap!AX4 -> C1C | AR9: =CO32M_LMP_GMX_UniqueMap!AY4 -> O2C | AS9: =AP9&"-"&AQ9&"-"&AR9 -> O2C-C1C-O2C | AU9: angle_coeff | AV9: 7 | AW9: {=_xlfn.XLOOKUP(AZ9,$AS$3:$AS$37,ROUND(0.119502868*$AO$3:$AO$37,3))} -> 69.9 | AX9: {=_xlfn.XLOOKUP(AZ9,$AS$3:$AS$37,ROUND($AN$3:$AN$37,3))} -> 118.18 | AY9: # | AZ9: O2C-C1C-O2C | BE9: =BE8+1 -> 7 | BF9: =MTFSI_LMP_GMX_UniqueMap!BV4 -> -15.611 | BG9: =MTFSI_LMP_GMX_UniqueMap!BW4 -> 0.703 | BH9: =MTFSI_LMP_GMX_UniqueMap!BX4 -> 20.506 | BI9: =MTFSI_LMP_GMX_UniqueMap!BY4 -> -5.598 | BJ9: =MTFSI_LMP_GMX_UniqueMap!BZ4 -> 0 | BK9: =MTFSI_LMP_GMX_UniqueMap!CA4 -> 0 | BL9: =SUM(BF9:BK9) -> -8.8817842e-16 | BM9: =MTFSI_LMP_GMX_UniqueMap!CB4&"-"&MTFSI_LMP_GMX_UniqueMap!CC4&"-"&MTFSI_LMP_GMX_UniqueMap!CD4&"-"&MTFSI_LMP_GMX_UniqueMap!CE4 -> C1MT-SMT-NMT-SMT | BP9: dihedral_coeff | BQ9: 7 | BR9: =BR62 -> 1.3 | BS9: =BS62 -> -0.2 | BT9: =BT62 -> 0.2 | BU9: =BU62 -> 0 | BV9: # | BW9: C1MT-C1MT-C1MT-C1V | BX9: From CCCC in butane
B10: =B9+1 -> 8 | C10: =CO32M_LMP_GMX_UniqueMap!N5 -> O2C | D10: =CO32M_LMP_GMX_UniqueMap!M5 -> 15.999 | E10: =B10 -> 8 | F10: =CO32M_LMP_GMX_UniqueMap!J5 -> 0.17 | G10: =CO32M_LMP_GMX_UniqueMap!K5 -> 3.12 | H10: # | I10: O2-COI/SEI | K10: pair_coeff | L10: =E10 -> 8 | M10: =E10 -> 8 | N10: =F10 -> 0.17 | O10: =G10 -> 3.12 | P10: =2.5*O10 -> 7.8 | Q10: =H10&" "&I10 -> # O2-COI/SEI | U10: =U9+1 -> 8 | V10: =MTFSI_LMP_GMX_UniqueMap!AB5 -> 0.1327 | W10: =MTFSI_LMP_GMX_UniqueMap!AC5 -> 179075.2 | X10: =MTFSI_LMP_GMX_UniqueMap!AD5 -> O1MT | Y10: =MTFSI_LMP_GMX_UniqueMap!AE5 -> C2MT | Z10: =X10&"-"&Y10 -> O1MT-C2MT | AB10: bond_coeff | AC10: 8 | AD10: {=_xlfn.XLOOKUP(AG10,$Z$3:$Z$22,ROUND(0.00119502868*$W$3:$W$22,2))} -> 317 | AE10: {=_xlfn.XLOOKUP(AG10,$Z$3:$Z$22,ROUND(10*$V$3:$V$22,4))} -> 1.522 | AF10: # | AG10: C2MT-C1MT | AM10: =AM9+1 -> 8 | AN10: =MTFSI_LMP_GMX_UniqueMap!AU3 -> 104.36 | AO10: =MTFSI_LMP_GMX_UniqueMap!AV3 -> 658.311 | AP10: =MTFSI_LMP_GMX_UniqueMap!AW3 -> C1MT | AQ10: =MTFSI_LMP_GMX_UniqueMap!AX3 -> SMT | AR10: =MTFSI_LMP_GMX_UniqueMap!AY3 -> NMT | AS10: =AP10&"-"&AQ10&"-"&AR10 -> C1MT-SMT-NMT | AU10: angle_coeff | AV10: 8 | AW10: {=_xlfn.XLOOKUP(AZ10,$AS$3:$AS$37,ROUND(0.119502868*$AO$3:$AO$37,3))} -> 58.35 | AX10: {=_xlfn.XLOOKUP(AZ10,$AS$3:$AS$37,ROUND($AN$3:$AN$37,3))} -> 112.7 | AY10: # | AZ10: C1MT-C1MT-C1MT | BE10: =BE9+1 -> 8 | BF10: =MTFSI_LMP_GMX_UniqueMap!BV5 -> 0.628 | BG10: =MTFSI_LMP_GMX_UniqueMap!BW5 -> 1.883 | BH10: =MTFSI_LMP_GMX_UniqueMap!BX5 -> 0 | BI10: =MTFSI_LMP_GMX_UniqueMap!BY5 -> -2.51 | BJ10: =MTFSI_LMP_GMX_UniqueMap!BZ5 -> 0 | BK10: =MTFSI_LMP_GMX_UniqueMap!CA5 -> 0 | BL10: =SUM(BF10:BK10) -> 0.001 | BM10: =MTFSI_LMP_GMX_UniqueMap!CB5&"-"&MTFSI_LMP_GMX_UniqueMap!CC5&"-"&MTFSI_LMP_GMX_UniqueMap!CD5&"-"&MTFSI_LMP_GMX_UniqueMap!CE5 -> C1MT-C1MT-C1MT-HMT | BP10: dihedral_coeff | BQ10: 8 | BR10: =BR63 -> -2.06 | BS10: =BS63 -> -0.313 | BT10: =BT63 -> 0.315 | BU10: =BU63 -> 0 | BV10: # | BW10: C2MT-C1MT-C1MT-C1MT | BX10: From CCCC in butyric acid
B11: =B10+1 -> 9 | C11: =MTFSI_LMP_GMX_UniqueMap!N5 -> C1MT | D11: =MTFSI_LMP_GMX_UniqueMap!M5 -> 12.011 | E11: =B11 -> 9 | F11: =MTFSI_LMP_GMX_UniqueMap!J5 -> 0.066 | G11: =MTFSI_LMP_GMX_UniqueMap!K5 -> 3.5 | H11: # | I11: C1-MT/Bulk | K11: pair_coeff | L11: =E11 -> 9 | M11: =E11 -> 9 | N11: =F11 -> 0.066 | O11: =G11 -> 3.5 | P11: =2.5*O11 -> 8.75 | Q11: =H11&" "&I11 -> # C1-MT/Bulk | U11: =U10+1 -> 9 | V11: =MTFSI_LMP_GMX_UniqueMap!AB6 -> 0.136 | W11: =MTFSI_LMP_GMX_UniqueMap!AC6 -> 307105.6 | X11: =MTFSI_LMP_GMX_UniqueMap!AD6 -> FMT | Y11: =MTFSI_LMP_GMX_UniqueMap!AE6 -> C1MT | Z11: =X11&"-"&Y11 -> FMT-C1MT | AB11: bond_coeff | AC11: 9 | AD11: {=_xlfn.XLOOKUP(AG11,$Z$3:$Z$22,ROUND(0.00119502868*$W$3:$W$22,2))} -> 367 | AE11: {=_xlfn.XLOOKUP(AG11,$Z$3:$Z$22,ROUND(10*$V$3:$V$22,4))} -> 1.36 | AF11: # | AG11: FMT-C1MT | AM11: =AM10+1 -> 9 | AN11: =MTFSI_LMP_GMX_UniqueMap!AU4 -> 104.36 | AO11: =MTFSI_LMP_GMX_UniqueMap!AV4 -> 658.311 | AP11: =MTFSI_LMP_GMX_UniqueMap!AW4 -> NMT | AQ11: =MTFSI_LMP_GMX_UniqueMap!AX4 -> SMT | AR11: =MTFSI_LMP_GMX_UniqueMap!AY4 -> O3MT | AS11: =AP11&"-"&AQ11&"-"&AR11 -> NMT-SMT-O3MT | AU11: angle_coeff | AV11: 9 | AW11: =AW10 -> 58.35 | AX11: =AX10 -> 112.7 | AY11: # | AZ11: C1MT-C1MT-C1V | BA11: Same as C1MT-C1MT-C1MT | BE11: =BE10+1 -> 9 | BF11: =MTFSI_LMP_GMX_UniqueMap!BV6 -> 2.874 | BG11: =MTFSI_LMP_GMX_UniqueMap!BW6 -> 0.582 | BH11: =MTFSI_LMP_GMX_UniqueMap!BX6 -> 2.092 | BI11: =MTFSI_LMP_GMX_UniqueMap!BY6 -> -5.548 | BJ11: =MTFSI_LMP_GMX_UniqueMap!BZ6 -> 0 | BK11: =MTFSI_LMP_GMX_UniqueMap!CA6 -> 0 | BL11: =SUM(BF11:BK11) -> 0 | BM11: =MTFSI_LMP_GMX_UniqueMap!CB6&"-"&MTFSI_LMP_GMX_UniqueMap!CC6&"-"&MTFSI_LMP_GMX_UniqueMap!CD6&"-"&MTFSI_LMP_GMX_UniqueMap!CE6 -> C1MT-C1MT-C1MT-O1MT | BP11: dihedral_coeff | BQ11: 9 | BR11: {=ROUND(0.239005736*(-2*_xlfn.XLOOKUP(BW11,$BM$3:$BM$54,ROUND($BG$3:$BG$54,5)) - 1.5*_xlfn.XLOOKUP(BW11,$BM$3:$BM$54,ROUND($BI$3:$BI$54,5))),3)} -> 0 | BS11: {=ROUND(0.239005736*(_xlfn.XLOOKUP(BW11,$BM$3:$BM$54,ROUND($BF$3:$BF$54,5)) + _xlfn.XLOOKUP(BW11,$BM$3:$BM$54,ROUND($BG$3:$BG$54,5)) + _xlfn.XLOOKUP(BW11,$BM$3:$BM$54,ROUND($BI$3:$BI$54,5))),3)} -> 0 | BT11: {=ROUND(0.239005736*(-0.5*_xlfn.XLOOKUP(BW11,$BM$3:$BM$54,ROUND($BI$3:$BI$54,5))),3)} -> 0.3 | BU11: {=ROUND(0.239005736*(-0.25*_xlfn.XLOOKUP(BW11,$BM$3:$BM$54,ROUND($BJ$3:$BJ$54,5))),3)} -> 0 | BV11: # | BW11: C1MT-C1MT-C1MT-HMT
B12: 10 | C12: =VEC_LMP_GMX_UniqueMap!N6 -> C1V | D12: =VEC_LMP_GMX_UniqueMap!M6 -> 12.011 | E12: =B12 -> 10 | F12: =VEC_LMP_GMX_UniqueMap!J6 -> 0.066 | G12: =VEC_LMP_GMX_UniqueMap!K6 -> 3.5 | H12: # | I12: C1-VEC/Bulk | K12: pair_coeff | L12: =E12 -> 10 | M12: =E12 -> 10 | N12: =F12 -> 0.066 | O12: =G12 -> 3.5 | P12: =2.5*O12 -> 8.75 | Q12: =H12&" "&I12 -> # C1-VEC/Bulk | U12: =U11+1 -> 10 | V12: =MTFSI_LMP_GMX_UniqueMap!AB7 -> 0.141 | W12: =MTFSI_LMP_GMX_UniqueMap!AC7 -> 267776 | X12: =MTFSI_LMP_GMX_UniqueMap!AD7 -> C1MT | Y12: =MTFSI_LMP_GMX_UniqueMap!AE7 -> O1MT | Z12: =X12&"-"&Y12 -> C1MT-O1MT | AB12: bond_coeff | AC12: 10 | AD12: {=_xlfn.XLOOKUP(AG12,$Z$3:$Z$22,ROUND(0.00119502868*$W$3:$W$22,2))} -> 340 | AE12: {=_xlfn.XLOOKUP(AG12,$Z$3:$Z$22,ROUND(10*$V$3:$V$22,4))} -> 1.09 | AF12: # | AG12: C1MT-HMT | AM12: =AM11+1 -> 10 | AN12: =MTFSI_LMP_GMX_UniqueMap!AU5 -> 107.8 | AO12: =MTFSI_LMP_GMX_UniqueMap!AV5 -> 276.144 | AP12: =MTFSI_LMP_GMX_UniqueMap!AW5 -> HMT | AQ12: =MTFSI_LMP_GMX_UniqueMap!AX5 -> C1MT | AR12: =MTFSI_LMP_GMX_UniqueMap!AY5 -> HMT | AS12: =AP12&"-"&AQ12&"-"&AR12 -> HMT-C1MT-HMT | AU12: angle_coeff | AV12: 10 | AW12: {=_xlfn.XLOOKUP(AZ12,$AS$3:$AS$37,ROUND(0.119502868*$AO$3:$AO$37,3))} -> 63 | AX12: {=_xlfn.XLOOKUP(AZ12,$AS$3:$AS$37,ROUND($AN$3:$AN$37,3))} -> 111.1 | AY12: # | AZ12: C1MT-C1MT-C2MT | BE12: =BE11+1 -> 10 | BF12: =MTFSI_LMP_GMX_UniqueMap!BV7 -> -2.197 | BG12: =MTFSI_LMP_GMX_UniqueMap!BW7 -> 5.201 | BH12: =MTFSI_LMP_GMX_UniqueMap!BX7 -> 0.527 | BI12: =MTFSI_LMP_GMX_UniqueMap!BY7 -> -3.531 | BJ12: =MTFSI_LMP_GMX_UniqueMap!BZ7 -> 0 | BK12: =MTFSI_LMP_GMX_UniqueMap!CA7 -> 0 | BL12: =SUM(BF12:BK12) -> -4.4408921e-16 | BM12: =MTFSI_LMP_GMX_UniqueMap!CB7&"-"&MTFSI_LMP_GMX_UniqueMap!CC7&"-"&MTFSI_LMP_GMX_UniqueMap!CD7&"-"&MTFSI_LMP_GMX_UniqueMap!CE7 -> C1MT-C1MT-O1MT-C2MT | BP12: dihedral_coeff | BQ12: 10 | BR12: {=ROUND(0.239005736*(-2*_xlfn.XLOOKUP(BW12,$BM$3:$BM$54,ROUND($BG$3:$BG$54,5)) - 1.5*_xlfn.XLOOKUP(BW12,$BM$3:$BM$54,ROUND($BI$3:$BI$54,5))),3)} -> 1.711 | BS12: {=ROUND(0.239005736*(_xlfn.XLOOKUP(BW12,$BM$3:$BM$54,ROUND($BF$3:$BF$54,5)) + _xlfn.XLOOKUP(BW12,$BM$3:$BM$54,ROUND($BG$3:$BG$54,5)) + _xlfn.XLOOKUP(BW12,$BM$3:$BM$54,ROUND($BI$3:$BI$54,5))),3)} -> -0.5 | BT12: {=ROUND(0.239005736*(-0.5*_xlfn.XLOOKUP(BW12,$BM$3:$BM$54,ROUND($BI$3:$BI$54,5))),3)} -> 0.663 | BU12: {=ROUND(0.239005736*(-0.25*_xlfn.XLOOKUP(BW12,$BM$3:$BM$54,ROUND($BJ$3:$BJ$54,5))),3)} -> 0 | BV12: # | BW12: C1MT-C1MT-C1MT-O1MT
B13: 11 | C13: =MTFSI_LMP_GMX_UniqueMap!N6 -> C2MT | D13: =MTFSI_LMP_GMX_UniqueMap!M6 -> 12.011 | E13: =B13 -> 11 | F13: =MTFSI_LMP_GMX_UniqueMap!J6 -> 0.07 | G13: =MTFSI_LMP_GMX_UniqueMap!K6 -> 3.55 | H13: # | I13: C2-MT/Bulk | K13: pair_coeff | L13: =E13 -> 11 | M13: =E13 -> 11 | N13: =F13 -> 0.07 | O13: =G13 -> 3.55 | P13: =2.5*O13 -> 8.875 | Q13: =H13&" "&I13 -> # C2-MT/Bulk | U13: =U12+1 -> 11 | V13: =MTFSI_LMP_GMX_UniqueMap!AB8 -> 0.144 | W13: =MTFSI_LMP_GMX_UniqueMap!AC8 -> 585760 | X13: =MTFSI_LMP_GMX_UniqueMap!AD8 -> O3MT | Y13: =MTFSI_LMP_GMX_UniqueMap!AE8 -> SMT | Z13: =X13&"-"&Y13 -> O3MT-SMT | AB13: bond_coeff | AC13: 11 | AD13: {=_xlfn.XLOOKUP(AG13,$Z$3:$Z$22,ROUND(0.00119502868*$W$3:$W$22,2))} -> 320 | AE13: {=_xlfn.XLOOKUP(AG13,$Z$3:$Z$22,ROUND(10*$V$3:$V$22,4))} -> 1.41 | AF13: # | AG13: C1MT-O1MT | AM13: =AM12+1 -> 11 | AN13: =MTFSI_LMP_GMX_UniqueMap!AU6 -> 108.6 | AO13: =MTFSI_LMP_GMX_UniqueMap!AV6 -> 418.4 | AP13: =MTFSI_LMP_GMX_UniqueMap!AW6 -> C1MT | AQ13: =MTFSI_LMP_GMX_UniqueMap!AX6 -> C1MT | AR13: =MTFSI_LMP_GMX_UniqueMap!AY6 -> SMT | AS13: =AP13&"-"&AQ13&"-"&AR13 -> C1MT-C1MT-SMT | AU13: angle_coeff | AV13: 11 | AW13: {=_xlfn.XLOOKUP(AZ13,$AS$3:$AS$37,ROUND(0.119502868*$AO$3:$AO$37,3))} -> 37.5 | AX13: {=_xlfn.XLOOKUP(AZ13,$AS$3:$AS$37,ROUND($AN$3:$AN$37,3))} -> 110.7 | AY13: # | AZ13: HMT-C1MT-C1MT | BE13: =BE12+1 -> 11 | BF13: =MTFSI_LMP_GMX_UniqueMap!BV8 -> 31.206 | BG13: =MTFSI_LMP_GMX_UniqueMap!BW8 -> -9.768 | BH13: =MTFSI_LMP_GMX_UniqueMap!BX8 -> -21.439 | BI13: =MTFSI_LMP_GMX_UniqueMap!BY8 -> 0 | BJ13: =MTFSI_LMP_GMX_UniqueMap!BZ8 -> 0 | BK13: =MTFSI_LMP_GMX_UniqueMap!CA8 -> 0 | BL13: =SUM(BF13:BK13) -> -0.001 | BM13: =MTFSI_LMP_GMX_UniqueMap!CB8&"-"&MTFSI_LMP_GMX_UniqueMap!CC8&"-"&MTFSI_LMP_GMX_UniqueMap!CD8&"-"&MTFSI_LMP_GMX_UniqueMap!CE8 -> C1MT-O1MT-C2MT-C1MT | BP13: dihedral_coeff | BQ13: 11 | BR13: {=ROUND(0.239005736*(-2*_xlfn.XLOOKUP(BW13,$BM$3:$BM$54,ROUND($BG$3:$BG$54,5)) - 1.5*_xlfn.XLOOKUP(BW13,$BM$3:$BM$54,ROUND($BI$3:$BI$54,5))),3)} -> 1.262 | BS13: {=ROUND(0.239005736*(_xlfn.XLOOKUP(BW13,$BM$3:$BM$54,ROUND($BF$3:$BF$54,5)) + _xlfn.XLOOKUP(BW13,$BM$3:$BM$54,ROUND($BG$3:$BG$54,5)) + _xlfn.XLOOKUP(BW13,$BM$3:$BM$54,ROUND($BI$3:$BI$54,5))),3)} -> -0.198 | BT13: {=ROUND(0.239005736*(-0.5*_xlfn.XLOOKUP(BW13,$BM$3:$BM$54,ROUND($BI$3:$BI$54,5))),3)} -> 0.465 | BU13: {=ROUND(0.239005736*(-0.25*_xlfn.XLOOKUP(BW13,$BM$3:$BM$54,ROUND($BJ$3:$BJ$54,5))),3)} -> 0 | BV13: # | BW13: SMT-C1MT-C1MT-C1MT
B14: 12 | C14: =VEC_LMP_GMX_UniqueMap!N7 -> C2V | D14: =VEC_LMP_GMX_UniqueMap!M7 -> 12.011 | E14: =B14 -> 12 | F14: =VEC_LMP_GMX_UniqueMap!J7 -> 0.07 | G14: =VEC_LMP_GMX_UniqueMap!K7 -> 3.55 | H14: # | I14: C2-VEC/Bulk | K14: pair_coeff | L14: =E14 -> 12 | M14: =E14 -> 12 | N14: =F14 -> 0.07 | O14: =G14 -> 3.55 | P14: =2.5*O14 -> 8.875 | Q14: =H14&" "&I14 -> # C2-VEC/Bulk | U14: =U13+1 -> 12 | V14: =MTFSI_LMP_GMX_UniqueMap!AB9 -> 0.1522 | W14: =MTFSI_LMP_GMX_UniqueMap!AC9 -> 265265.6 | X14: =MTFSI_LMP_GMX_UniqueMap!AD9 -> C2MT | Y14: =MTFSI_LMP_GMX_UniqueMap!AE9 -> C1MT | Z14: =X14&"-"&Y14 -> C2MT-C1MT | AB14: bond_coeff | AC14: 12 | AD14: {=_xlfn.XLOOKUP(AG14,$Z$3:$Z$22,ROUND(0.00119502868*$W$3:$W$22,2))} -> 340 | AE14: {=_xlfn.XLOOKUP(AG14,$Z$3:$Z$22,ROUND(10*$V$3:$V$22,4))} -> 1.77 | AF14: # | AG14: SMT-C1MT | AM14: =AM13+1 -> 12 | AN14: =MTFSI_LMP_GMX_UniqueMap!AU7 -> 108.9 | AO14: =MTFSI_LMP_GMX_UniqueMap!AV7 -> 619.232 | AP14: =MTFSI_LMP_GMX_UniqueMap!AW7 -> C1MT | AQ14: =MTFSI_LMP_GMX_UniqueMap!AX7 -> SMT | AR14: =MTFSI_LMP_GMX_UniqueMap!AY7 -> O3MT | AS14: =AP14&"-"&AQ14&"-"&AR14 -> C1MT-SMT-O3MT | AU14: angle_coeff | AV14: 12 | AW14: {=_xlfn.XLOOKUP(AZ14,$AS$3:$AS$37,ROUND(0.119502868*$AO$3:$AO$37,3))} -> 50 | AX14: {=_xlfn.XLOOKUP(AZ14,$AS$3:$AS$37,ROUND($AN$3:$AN$37,3))} -> 109.5 | AY14: # | AZ14: O1MT-C1MT-C1MT | BE14: =BE13+1 -> 12 | BF14: =MTFSI_LMP_GMX_UniqueMap!BV9 -> 21.439 | BG14: =MTFSI_LMP_GMX_UniqueMap!BW9 -> 0 | BH14: =MTFSI_LMP_GMX_UniqueMap!BX9 -> -21.439 | BI14: =MTFSI_LMP_GMX_UniqueMap!BY9 -> 0 | BJ14: =MTFSI_LMP_GMX_UniqueMap!BZ9 -> 0 | BK14: =MTFSI_LMP_GMX_UniqueMap!CA9 -> 0 | BL14: =SUM(BF14:BK14) -> 0 | BM14: =MTFSI_LMP_GMX_UniqueMap!CB9&"-"&MTFSI_LMP_GMX_UniqueMap!CC9&"-"&MTFSI_LMP_GMX_UniqueMap!CD9&"-"&MTFSI_LMP_GMX_UniqueMap!CE9 -> C1MT-O1MT-C2MT-O2MT | BP14: dihedral_coeff | BQ14: 12 | BR14: =BR62 -> 1.3 | BS14: =BS62 -> -0.2 | BT14: =BT62 -> 0.2 | BU14: =BU62 -> 0 | BV14: # | BW14: C1MT-C1MT-C1V-C1V | BX14: From CCCC in butane
B15: 13 | C15: =MTFSI_LMP_GMX_UniqueMap!N4 -> FMT | D15: =MTFSI_LMP_GMX_UniqueMap!M4 -> 18.998 | E15: =B15 -> 13 | F15: =MTFSI_LMP_GMX_UniqueMap!J4 -> 0.06 | G15: =MTFSI_LMP_GMX_UniqueMap!K4 -> 2.9 | H15: # | I15: F-MT/Bulk | K15: pair_coeff | L15: =E15 -> 13 | M15: =E15 -> 13 | N15: =F15 -> 0.06 | O15: =G15 -> 2.9 | P15: =2.5*O15 -> 7.25 | Q15: =H15&" "&I15 -> # F-MT/Bulk | U15: =U14+1 -> 13 | V15: =MTFSI_LMP_GMX_UniqueMap!AB10 -> 0.1529 | W15: =MTFSI_LMP_GMX_UniqueMap!AC10 -> 224262.4 | X15: =MTFSI_LMP_GMX_UniqueMap!AD10 -> C1MT | Y15: =MTFSI_LMP_GMX_UniqueMap!AE10 -> C1MT | Z15: =X15&"-"&Y15 -> C1MT-C1MT | AB15: bond_coeff | AC15: 13 | AD15: {=_xlfn.XLOOKUP(AG15,$Z$3:$Z$22,ROUND(0.00119502868*$W$3:$W$22,2))} -> 268 | AE15: {=_xlfn.XLOOKUP(AG15,$Z$3:$Z$22,ROUND(10*$V$3:$V$22,4))} -> 1.529 | AF15: # | AG15: C1V-C1V | AM15: =AM14+1 -> 13 | AN15: =MTFSI_LMP_GMX_UniqueMap!AU8 -> 109.1 | AO15: =MTFSI_LMP_GMX_UniqueMap!AV8 -> 644.336 | AP15: =MTFSI_LMP_GMX_UniqueMap!AW8 -> FMT | AQ15: =MTFSI_LMP_GMX_UniqueMap!AX8 -> C1MT | AR15: =MTFSI_LMP_GMX_UniqueMap!AY8 -> FMT | AS15: =AP15&"-"&AQ15&"-"&AR15 -> FMT-C1MT-FMT | AU15: angle_coeff | AV15: 13 | AW15: {=_xlfn.XLOOKUP(AZ15,$AS$3:$AS$37,ROUND(0.119502868*$AO$3:$AO$37,3))} -> 50 | AX15: {=_xlfn.XLOOKUP(AZ15,$AS$3:$AS$37,ROUND($AN$3:$AN$37,3))} -> 108.6 | AY15: # | AZ15: C1MT-C1MT-SMT | BE15: =BE14+1 -> 13 | BF15: =MTFSI_LMP_GMX_UniqueMap!BV10 -> 0 | BG15: =MTFSI_LMP_GMX_UniqueMap!BW10 -> 0 | BH15: =MTFSI_LMP_GMX_UniqueMap!BX10 -> 0 | BI15: =MTFSI_LMP_GMX_UniqueMap!BY10 -> 0 | BJ15: =MTFSI_LMP_GMX_UniqueMap!BZ10 -> 0 | BK15: =MTFSI_LMP_GMX_UniqueMap!CA10 -> 0 | BL15: =SUM(BF15:BK15) -> 0 | BM15: =MTFSI_LMP_GMX_UniqueMap!CB10&"-"&MTFSI_LMP_GMX_UniqueMap!CC10&"-"&MTFSI_LMP_GMX_UniqueMap!CD10&"-"&MTFSI_LMP_GMX_UniqueMap!CE10 -> FMT-C1MT-SMT-NMT | BP15: dihedral_coeff | BQ15: 13 | BR15: =BR11 -> 0 | BS15: =BS11 -> 0 | BT15: =BT11 -> 0.3 | BU15: =BU11 -> 0 | BV15: # | BW15: C1MT-C1MT-C1V-HV | BX15: ="Same as "&BW11 -> Same as C1MT-C1MT-C1MT-HMT
B16: 14 | C16: =MTFSI_LMP_GMX_UniqueMap!N3 -> HMT | D16: =MTFSI_LMP_GMX_UniqueMap!M3 -> 1.008 | E16: =B16 -> 14 | F16: =MTFSI_LMP_GMX_UniqueMap!J3 -> 0.03 | G16: =MTFSI_LMP_GMX_UniqueMap!K3 -> 2.5 | H16: # | I16: H-MT/Bulk | K16: pair_coeff | L16: =E16 -> 14 | M16: =E16 -> 14 | N16: =F16 -> 0.03 | O16: =G16 -> 2.5 | P16: =2.5*O16 -> 6.25 | Q16: =H16&" "&I16 -> # H-MT/Bulk | U16: =U15+1 -> 14 | V16: =MTFSI_LMP_GMX_UniqueMap!AB11 -> 0.173 | W16: =MTFSI_LMP_GMX_UniqueMap!AC11 -> 209200 | X16: =MTFSI_LMP_GMX_UniqueMap!AD11 -> NMT | Y16: =MTFSI_LMP_GMX_UniqueMap!AE11 -> SMT | Z16: =X16&"-"&Y16 -> NMT-SMT | AB16: bond_coeff | AC16: 14 | AD16: {=_xlfn.XLOOKUP(AG16,$Z$3:$Z$22,ROUND(0.00119502868*$W$3:$W$22,2))} -> 340 | AE16: {=_xlfn.XLOOKUP(AG16,$Z$3:$Z$22,ROUND(10*$V$3:$V$22,4))} -> 1.09 | AF16: # | AG16: C1V-HV | AM16: =AM15+1 -> 14 | AN16: =MTFSI_LMP_GMX_UniqueMap!AU9 -> 109.5 | AO16: =MTFSI_LMP_GMX_UniqueMap!AV9 -> 418.4 | AP16: =MTFSI_LMP_GMX_UniqueMap!AW9 -> O1MT | AQ16: =MTFSI_LMP_GMX_UniqueMap!AX9 -> C1MT | AR16: =MTFSI_LMP_GMX_UniqueMap!AY9 -> C1MT | AS16: =AP16&"-"&AQ16&"-"&AR16 -> O1MT-C1MT-C1MT | AU16: angle_coeff | AV16: 14 | AW16: =AW10 -> 58.35 | AX16: =AX10 -> 112.7 | AY16: # | AZ16: C1MT-C1V-C1V | BA16: Same as C1MT-C1MT-C1MT | BE16: =BE15+1 -> 14 | BF16: =MTFSI_LMP_GMX_UniqueMap!BV11 -> 0 | BG16: =MTFSI_LMP_GMX_UniqueMap!BW11 -> 0 | BH16: =MTFSI_LMP_GMX_UniqueMap!BX11 -> 0 | BI16: =MTFSI_LMP_GMX_UniqueMap!BY11 -> 0 | BJ16: =MTFSI_LMP_GMX_UniqueMap!BZ11 -> 0 | BK16: =MTFSI_LMP_GMX_UniqueMap!CA11 -> 0 | BL16: =SUM(BF16:BK16) -> 0 | BM16: =MTFSI_LMP_GMX_UniqueMap!CB11&"-"&MTFSI_LMP_GMX_UniqueMap!CC11&"-"&MTFSI_LMP_GMX_UniqueMap!CD11&"-"&MTFSI_LMP_GMX_UniqueMap!CE11 -> FMT-C1MT-SMT-O3MT | BP16: dihedral_coeff | BQ16: 14 | BR16: {=ROUND(0.239005736*(-2*_xlfn.XLOOKUP(BW16,$BM$3:$BM$54,ROUND($BG$3:$BG$54,5)) - 1.5*_xlfn.XLOOKUP(BW16,$BM$3:$BM$54,ROUND($BI$3:$BI$54,5))),3)} -> 0 | BS16: {=ROUND(0.239005736*(_xlfn.XLOOKUP(BW16,$BM$3:$BM$54,ROUND($BF$3:$BF$54,5)) + _xlfn.XLOOKUP(BW16,$BM$3:$BM$54,ROUND($BG$3:$BG$54,5)) + _xlfn.XLOOKUP(BW16,$BM$3:$BM$54,ROUND($BI$3:$BI$54,5))),3)} -> 0 | BT16: {=ROUND(0.239005736*(-0.5*_xlfn.XLOOKUP(BW16,$BM$3:$BM$54,ROUND($BI$3:$BI$54,5))),3)} -> -0.553 | BU16: {=ROUND(0.239005736*(-0.25*_xlfn.XLOOKUP(BW16,$BM$3:$BM$54,ROUND($BJ$3:$BJ$54,5))),3)} -> 0 | BV16: # | BW16: O1MT-C2MT-C1MT-C1MT
B17: =B16+1 -> 15 | C17: =VEC_LMP_GMX_UniqueMap!N3 -> HV | D17: =VEC_LMP_GMX_UniqueMap!M3 -> 1.008 | E17: =B17 -> 15 | F17: =VEC_LMP_GMX_UniqueMap!J3 -> 0.03 | G17: =VEC_LMP_GMX_UniqueMap!K3 -> 2.5 | H17: # | I17: H-VEC/Bulk | K17: pair_coeff | L17: =E17 -> 15 | M17: =E17 -> 15 | N17: =F17 -> 0.03 | O17: =G17 -> 2.5 | P17: =2.5*O17 -> 6.25 | Q17: =H17&" "&I17 -> # H-VEC/Bulk | U17: =U16+1 -> 15 | V17: =MTFSI_LMP_GMX_UniqueMap!AB12 -> 0.177 | W17: =MTFSI_LMP_GMX_UniqueMap!AC12 -> 284512 | X17: =MTFSI_LMP_GMX_UniqueMap!AD12 -> SMT | Y17: =MTFSI_LMP_GMX_UniqueMap!AE12 -> C1MT | Z17: =X17&"-"&Y17 -> SMT-C1MT | AB17: bond_coeff | AC17: 15 | AD17: {=_xlfn.XLOOKUP(AG17,$Z$3:$Z$22,ROUND(0.00119502868*$W$3:$W$22,2))} -> 320 | AE17: {=_xlfn.XLOOKUP(AG17,$Z$3:$Z$22,ROUND(10*$V$3:$V$22,4))} -> 1.41 | AF17: # | AG17: O1V-C1V | AM17: =AM16+1 -> 15 | AN17: =MTFSI_LMP_GMX_UniqueMap!AU10 -> 109.5 | AO17: =MTFSI_LMP_GMX_UniqueMap!AV10 -> 292.88 | AP17: =MTFSI_LMP_GMX_UniqueMap!AW10 -> O1MT | AQ17: =MTFSI_LMP_GMX_UniqueMap!AX10 -> C1MT | AR17: =MTFSI_LMP_GMX_UniqueMap!AY10 -> HMT | AS17: =AP17&"-"&AQ17&"-"&AR17 -> O1MT-C1MT-HMT | AU17: angle_coeff | AV17: 15 | AW17: =AW3 -> 37.5 | AX17: =AX3 -> 110.7 | AY17: # | AZ17: C1MT-C1V-HV | BA17: Same as HMT-C1MT-C1MT | BE17: =BE16+1 -> 15 | BF17: =MTFSI_LMP_GMX_UniqueMap!BV12 -> -0.209 | BG17: =MTFSI_LMP_GMX_UniqueMap!BW12 -> -0.628 | BH17: =MTFSI_LMP_GMX_UniqueMap!BX12 -> 0 | BI17: =MTFSI_LMP_GMX_UniqueMap!BY12 -> 0.837 | BJ17: =MTFSI_LMP_GMX_UniqueMap!BZ12 -> 0 | BK17: =MTFSI_LMP_GMX_UniqueMap!CA12 -> 0 | BL17: =SUM(BF17:BK17) -> 0 | BM17: =MTFSI_LMP_GMX_UniqueMap!CB12&"-"&MTFSI_LMP_GMX_UniqueMap!CC12&"-"&MTFSI_LMP_GMX_UniqueMap!CD12&"-"&MTFSI_LMP_GMX_UniqueMap!CE12 -> HMT-C1MT-C1MT-C2MT | BP17: dihedral_coeff | BQ17: 15 | BR17: {=ROUND(0.239005736*(-2*_xlfn.XLOOKUP(BW17,$BM$3:$BM$54,ROUND($BG$3:$BG$54,5)) - 1.5*_xlfn.XLOOKUP(BW17,$BM$3:$BM$54,ROUND($BI$3:$BI$54,5))),3)} -> 0 | BS17: {=ROUND(0.239005736*(_xlfn.XLOOKUP(BW17,$BM$3:$BM$54,ROUND($BF$3:$BF$54,5)) + _xlfn.XLOOKUP(BW17,$BM$3:$BM$54,ROUND($BG$3:$BG$54,5)) + _xlfn.XLOOKUP(BW17,$BM$3:$BM$54,ROUND($BI$3:$BI$54,5))),3)} -> 0 | BT17: {=ROUND(0.239005736*(-0.5*_xlfn.XLOOKUP(BW17,$BM$3:$BM$54,ROUND($BI$3:$BI$54,5))),3)} -> 0 | BU17: {=ROUND(0.239005736*(-0.25*_xlfn.XLOOKUP(BW17,$BM$3:$BM$54,ROUND($BJ$3:$BJ$54,5))),3)} -> 0 | BV17: # | BW17: O2MT-C2MT-C1MT-C1MT
B18: =B17+1 -> 16 | C18: =MTFSI_LMP_GMX_UniqueMap!N8 -> NMT | D18: =MTFSI_LMP_GMX_UniqueMap!M8 -> 14.007 | E18: =B18 -> 16 | F18: =MTFSI_LMP_GMX_UniqueMap!J8 -> 0.17 | G18: =MTFSI_LMP_GMX_UniqueMap!K8 -> 3.25 | H18: # | I18: N-MT/Bulk | K18: pair_coeff | L18: =E18 -> 16 | M18: =E18 -> 16 | N18: =F18 -> 0.17 | O18: =G18 -> 3.25 | P18: =2.5*O18 -> 8.125 | Q18: =H18&" "&I18 -> # N-MT/Bulk | U18: =U17+1 -> 16 | V18: =VEC_LMP_GMX_UniqueMap!AB3 -> 0.109 | W18: =VEC_LMP_GMX_UniqueMap!AC3 -> 284512 | X18: =VEC_LMP_GMX_UniqueMap!AD3 -> C1V | Y18: =VEC_LMP_GMX_UniqueMap!AE3 -> HV | Z18: =X18&"-"&Y18 -> C1V-HV | AB18: bond_coeff | AC18: 16 | AD18: {=_xlfn.XLOOKUP(AG18,$Z$3:$Z$22,ROUND(0.00119502868*$W$3:$W$22,2))} -> 214 | AE18: {=_xlfn.XLOOKUP(AG18,$Z$3:$Z$22,ROUND(10*$V$3:$V$22,4))} -> 1.327 | AF18: # | AG18: O1MT-C2MT | AM18: =AM17+1 -> 16 | AN18: =MTFSI_LMP_GMX_UniqueMap!AU11 -> 109.5 | AO18: =MTFSI_LMP_GMX_UniqueMap!AV11 -> 418.4 | AP18: =MTFSI_LMP_GMX_UniqueMap!AW11 -> SMT | AQ18: =MTFSI_LMP_GMX_UniqueMap!AX11 -> C1MT | AR18: =MTFSI_LMP_GMX_UniqueMap!AY11 -> FMT | AS18: =AP18&"-"&AQ18&"-"&AR18 -> SMT-C1MT-FMT | AU18: angle_coeff | AV18: 16 | AW18: {=_xlfn.XLOOKUP(AZ18,$AS$3:$AS$37,ROUND(0.119502868*$AO$3:$AO$37,3))} -> 81 | AX18: {=_xlfn.XLOOKUP(AZ18,$AS$3:$AS$37,ROUND($AN$3:$AN$37,3))} -> 111.4 | AY18: # | AZ18: C1MT-C2MT-O1MT | BE18: =BE17+1 -> 16 | BF18: =MTFSI_LMP_GMX_UniqueMap!BV13 -> 0.628 | BG18: =MTFSI_LMP_GMX_UniqueMap!BW13 -> 1.883 | BH18: =MTFSI_LMP_GMX_UniqueMap!BX13 -> 0 | BI18: =MTFSI_LMP_GMX_UniqueMap!BY13 -> -2.51 | BJ18: =MTFSI_LMP_GMX_UniqueMap!BZ13 -> 0 | BK18: =MTFSI_LMP_GMX_UniqueMap!CA13 -> 0 | BL18: =SUM(BF18:BK18) -> 0.001 | BM18: =MTFSI_LMP_GMX_UniqueMap!CB13&"-"&MTFSI_LMP_GMX_UniqueMap!CC13&"-"&MTFSI_LMP_GMX_UniqueMap!CD13&"-"&MTFSI_LMP_GMX_UniqueMap!CE13 -> HMT-C1MT-C1MT-C1MT | BP18: dihedral_coeff | BQ18: 16 | BR18: {=ROUND(0.239005736*(-2*_xlfn.XLOOKUP(BW18,$BM$3:$BM$54,ROUND($BG$3:$BG$54,5)) - 1.5*_xlfn.XLOOKUP(BW18,$BM$3:$BM$54,ROUND($BI$3:$BI$54,5))),3)} -> -1.22 | BS18: {=ROUND(0.239005736*(_xlfn.XLOOKUP(BW18,$BM$3:$BM$54,ROUND($BF$3:$BF$54,5)) + _xlfn.XLOOKUP(BW18,$BM$3:$BM$54,ROUND($BG$3:$BG$54,5)) + _xlfn.XLOOKUP(BW18,$BM$3:$BM$54,ROUND($BI$3:$BI$54,5))),3)} -> -0.126 | BT18: {=ROUND(0.239005736*(-0.5*_xlfn.XLOOKUP(BW18,$BM$3:$BM$54,ROUND($BI$3:$BI$54,5))),3)} -> 0.422 | BU18: {=ROUND(0.239005736*(-0.25*_xlfn.XLOOKUP(BW18,$BM$3:$BM$54,ROUND($BJ$3:$BJ$54,5))),3)} -> 0 | BV18: # | BW18: C1MT-C1MT-O1MT-C2MT
B19: =B18+1 -> 17 | C19: =MTFSI_LMP_GMX_UniqueMap!N7 -> O1MT | D19: =MTFSI_LMP_GMX_UniqueMap!M7 -> 15.999 | E19: =B19 -> 17 | F19: =MTFSI_LMP_GMX_UniqueMap!J7 -> 0.14 | G19: =MTFSI_LMP_GMX_UniqueMap!K7 -> 2.9 | H19: # | I19: O1-MT/Bulk | K19: pair_coeff | L19: =E19 -> 17 | M19: =E19 -> 17 | N19: =F19 -> 0.14 | O19: =G19 -> 2.9 | P19: =2.5*O19 -> 7.25 | Q19: =H19&" "&I19 -> # O1-MT/Bulk | U19: =U18+1 -> 17 | V19: =VEC_LMP_GMX_UniqueMap!AB4 -> 0.1229 | W19: =VEC_LMP_GMX_UniqueMap!AC4 -> 476976 | X19: =VEC_LMP_GMX_UniqueMap!AD4 -> O2V | Y19: =VEC_LMP_GMX_UniqueMap!AE4 -> C2V | Z19: =X19&"-"&Y19 -> O2V-C2V | AB19: bond_coeff | AC19: 17 | AD19: {=_xlfn.XLOOKUP(AG19,$Z$3:$Z$22,ROUND(0.00119502868*$W$3:$W$22,2))} -> 570 | AE19: {=_xlfn.XLOOKUP(AG19,$Z$3:$Z$22,ROUND(10*$V$3:$V$22,4))} -> 1.229 | AF19: # | AG19: O2MT-C2MT | AM19: =AM18+1 -> 17 | AN19: =MTFSI_LMP_GMX_UniqueMap!AU12 -> 109.5 | AO19: =MTFSI_LMP_GMX_UniqueMap!AV12 -> 292.88 | AP19: =MTFSI_LMP_GMX_UniqueMap!AW12 -> SMT | AQ19: =MTFSI_LMP_GMX_UniqueMap!AX12 -> C1MT | AR19: =MTFSI_LMP_GMX_UniqueMap!AY12 -> HMT | AS19: =AP19&"-"&AQ19&"-"&AR19 -> SMT-C1MT-HMT | AU19: angle_coeff | AV19: 17 | AW19: {=_xlfn.XLOOKUP(AZ19,$AS$3:$AS$37,ROUND(0.119502868*$AO$3:$AO$37,3))} -> 80 | AX19: {=_xlfn.XLOOKUP(AZ19,$AS$3:$AS$37,ROUND($AN$3:$AN$37,3))} -> 120.4 | AY19: # | AZ19: C1MT-C2MT-O2MT | BE19: =BE18+1 -> 17 | BF19: =MTFSI_LMP_GMX_UniqueMap!BV14 -> 0.628 | BG19: =MTFSI_LMP_GMX_UniqueMap!BW14 -> 1.883 | BH19: =MTFSI_LMP_GMX_UniqueMap!BX14 -> 0 | BI19: =MTFSI_LMP_GMX_UniqueMap!BY14 -> -2.51 | BJ19: =MTFSI_LMP_GMX_UniqueMap!BZ14 -> 0 | BK19: =MTFSI_LMP_GMX_UniqueMap!CA14 -> 0 | BL19: =SUM(BF19:BK19) -> 0.001 | BM19: =MTFSI_LMP_GMX_UniqueMap!CB14&"-"&MTFSI_LMP_GMX_UniqueMap!CC14&"-"&MTFSI_LMP_GMX_UniqueMap!CD14&"-"&MTFSI_LMP_GMX_UniqueMap!CE14 -> HMT-C1MT-C1MT-HMT | BP19: dihedral_coeff | BQ19: 17 | BR19: {=ROUND(0.239005736*(-2*_xlfn.XLOOKUP(BW19,$BM$3:$BM$54,ROUND($BG$3:$BG$54,5)) - 1.5*_xlfn.XLOOKUP(BW19,$BM$3:$BM$54,ROUND($BI$3:$BI$54,5))),3)} -> 0 | BS19: {=ROUND(0.239005736*(_xlfn.XLOOKUP(BW19,$BM$3:$BM$54,ROUND($BF$3:$BF$54,5)) + _xlfn.XLOOKUP(BW19,$BM$3:$BM$54,ROUND($BG$3:$BG$54,5)) + _xlfn.XLOOKUP(BW19,$BM$3:$BM$54,ROUND($BI$3:$BI$54,5))),3)} -> 0 | BT19: {=ROUND(0.239005736*(-0.5*_xlfn.XLOOKUP(BW19,$BM$3:$BM$54,ROUND($BI$3:$BI$54,5))),3)} -> 0 | BU19: {=ROUND(0.239005736*(-0.25*_xlfn.XLOOKUP(BW19,$BM$3:$BM$54,ROUND($BJ$3:$BJ$54,5))),3)} -> 0 | BV19: # | BW19: NMT-SMT-C1MT-C1MT
B20: =B19+1 -> 18 | C20: =VEC_LMP_GMX_UniqueMap!N4 -> O1V | D20: =VEC_LMP_GMX_UniqueMap!M4 -> 15.999 | E20: =B20 -> 18 | F20: =VEC_LMP_GMX_UniqueMap!J4 -> 0.14 | G20: =VEC_LMP_GMX_UniqueMap!K4 -> 2.9 | H20: # | I20: O1-VEC/Bulk | K20: pair_coeff | L20: =E20 -> 18 | M20: =E20 -> 18 | N20: =F20 -> 0.14 | O20: =G20 -> 2.9 | P20: =2.5*O20 -> 7.25 | Q20: =H20&" "&I20 -> # O1-VEC/Bulk | U20: =U19+1 -> 18 | V20: =VEC_LMP_GMX_UniqueMap!AB5 -> 0.1327 | W20: =VEC_LMP_GMX_UniqueMap!AC5 -> 179075.2 | X20: =VEC_LMP_GMX_UniqueMap!AD5 -> C2V | Y20: =VEC_LMP_GMX_UniqueMap!AE5 -> O1V | Z20: =X20&"-"&Y20 -> C2V-O1V | AB20: bond_coeff | AC20: 18 | AD20: {=_xlfn.XLOOKUP(AG20,$Z$3:$Z$22,ROUND(0.00119502868*$W$3:$W$22,2))} -> 214 | AE20: {=_xlfn.XLOOKUP(AG20,$Z$3:$Z$22,ROUND(10*$V$3:$V$22,4))} -> 1.327 | AF20: # | AG20: C2V-O1V | AM20: =AM19+1 -> 18 | AN20: =MTFSI_LMP_GMX_UniqueMap!AU13 -> 109.5 | AO20: =MTFSI_LMP_GMX_UniqueMap!AV13 -> 292.88 | AP20: =MTFSI_LMP_GMX_UniqueMap!AW13 -> C2MT | AQ20: =MTFSI_LMP_GMX_UniqueMap!AX13 -> C1MT | AR20: =MTFSI_LMP_GMX_UniqueMap!AY13 -> HMT | AS20: =AP20&"-"&AQ20&"-"&AR20 -> C2MT-C1MT-HMT | AU20: angle_coeff | AV20: 18 | AW20: {=_xlfn.XLOOKUP(AZ20,$AS$3:$AS$37,ROUND(0.119502868*$AO$3:$AO$37,3))} -> 83 | AX20: {=_xlfn.XLOOKUP(AZ20,$AS$3:$AS$37,ROUND($AN$3:$AN$37,3))} -> 116.9 | AY20: # | AZ20: C2MT-O1MT-C1MT | BE20: =BE19+1 -> 18 | BF20: =MTFSI_LMP_GMX_UniqueMap!BV15 -> 0.979 | BG20: =MTFSI_LMP_GMX_UniqueMap!BW15 -> 2.937 | BH20: =MTFSI_LMP_GMX_UniqueMap!BX15 -> 0 | BI20: =MTFSI_LMP_GMX_UniqueMap!BY15 -> -3.916 | BJ20: =MTFSI_LMP_GMX_UniqueMap!BZ15 -> 0 | BK20: =MTFSI_LMP_GMX_UniqueMap!CA15 -> 0 | BL20: =SUM(BF20:BK20) -> 0 | BM20: =MTFSI_LMP_GMX_UniqueMap!CB15&"-"&MTFSI_LMP_GMX_UniqueMap!CC15&"-"&MTFSI_LMP_GMX_UniqueMap!CD15&"-"&MTFSI_LMP_GMX_UniqueMap!CE15 -> HMT-C1MT-C1MT-O1MT | BP20: dihedral_coeff | BQ20: 18 | BR20: {=ROUND(0.239005736*(-2*_xlfn.XLOOKUP(BW20,$BM$3:$BM$54,ROUND($BG$3:$BG$54,5)) - 1.5*_xlfn.XLOOKUP(BW20,$BM$3:$BM$54,ROUND($BI$3:$BI$54,5))),3)} -> 0 | BS20: {=ROUND(0.239005736*(_xlfn.XLOOKUP(BW20,$BM$3:$BM$54,ROUND($BF$3:$BF$54,5)) + _xlfn.XLOOKUP(BW20,$BM$3:$BM$54,ROUND($BG$3:$BG$54,5)) + _xlfn.XLOOKUP(BW20,$BM$3:$BM$54,ROUND($BI$3:$BI$54,5))),3)} -> 0 | BT20: {=ROUND(0.239005736*(-0.5*_xlfn.XLOOKUP(BW20,$BM$3:$BM$54,ROUND($BI$3:$BI$54,5))),3)} -> 0 | BU20: {=ROUND(0.239005736*(-0.25*_xlfn.XLOOKUP(BW20,$BM$3:$BM$54,ROUND($BJ$3:$BJ$54,5))),3)} -> 0 | BV20: # | BW20: O3MT-SMT-C1MT-C1MT
B21: 19 | C21: =MTFSI_LMP_GMX_UniqueMap!N10 -> O2MT | D21: =MTFSI_LMP_GMX_UniqueMap!M10 -> 15.999 | E21: =B21 -> 19 | F21: =MTFSI_LMP_GMX_UniqueMap!J10 -> 0.21 | G21: =MTFSI_LMP_GMX_UniqueMap!K10 -> 2.96 | H21: # | I21: O2-MT/Bulk | K21: pair_coeff | L21: =E21 -> 19 | M21: =E21 -> 19 | N21: =F21 -> 0.21 | O21: =G21 -> 2.96 | P21: =2.5*O21 -> 7.4 | Q21: =H21&" "&I21 -> # O2-MT/Bulk | U21: =U20+1 -> 19 | V21: =VEC_LMP_GMX_UniqueMap!AB6 -> 0.141 | W21: =VEC_LMP_GMX_UniqueMap!AC6 -> 267776 | X21: =VEC_LMP_GMX_UniqueMap!AD6 -> O1V | Y21: =VEC_LMP_GMX_UniqueMap!AE6 -> C1V | Z21: =X21&"-"&Y21 -> O1V-C1V | AB21: bond_coeff | AC21: 19 | AD21: {=_xlfn.XLOOKUP(AG21,$Z$3:$Z$22,ROUND(0.00119502868*$W$3:$W$22,2))} -> 570 | AE21: {=_xlfn.XLOOKUP(AG21,$Z$3:$Z$22,ROUND(10*$V$3:$V$22,4))} -> 1.229 | AF21: # | AG21: O2V-C2V | AM21: =AM20+1 -> 19 | AN21: =MTFSI_LMP_GMX_UniqueMap!AU14 -> 110.7 | AO21: =MTFSI_LMP_GMX_UniqueMap!AV14 -> 313.8 | AP21: =MTFSI_LMP_GMX_UniqueMap!AW14 -> HMT | AQ21: =MTFSI_LMP_GMX_UniqueMap!AX14 -> C1MT | AR21: =MTFSI_LMP_GMX_UniqueMap!AY14 -> C1MT | AS21: =AP21&"-"&AQ21&"-"&AR21 -> HMT-C1MT-C1MT | AU21: angle_coeff | AV21: 19 | AW21: {=_xlfn.XLOOKUP(AZ21,$AS$3:$AS$37,ROUND(0.119502868*$AO$3:$AO$37,3))} -> 78.67 | AX21: {=_xlfn.XLOOKUP(AZ21,$AS$3:$AS$37,ROUND($AN$3:$AN$37,3))} -> 104.36 | AY21: # | AZ21: C1MT-SMT-NMT | BE21: =BE20+1 -> 19 | BF21: =MTFSI_LMP_GMX_UniqueMap!BV16 -> 0.414 | BG21: =MTFSI_LMP_GMX_UniqueMap!BW16 -> 1.243 | BH21: =MTFSI_LMP_GMX_UniqueMap!BX16 -> 0 | BI21: =MTFSI_LMP_GMX_UniqueMap!BY16 -> -1.657 | BJ21: =MTFSI_LMP_GMX_UniqueMap!BZ16 -> 0 | BK21: =MTFSI_LMP_GMX_UniqueMap!CA16 -> 0 | BL21: =SUM(BF21:BK21) -> 0 | BM21: =MTFSI_LMP_GMX_UniqueMap!CB16&"-"&MTFSI_LMP_GMX_UniqueMap!CC16&"-"&MTFSI_LMP_GMX_UniqueMap!CD16&"-"&MTFSI_LMP_GMX_UniqueMap!CE16 -> HMT-C1MT-O1MT-C2MT | BP21: dihedral_coeff | BQ21: 19 | BR21: =BR62 -> 1.3 | BS21: =BS62 -> -0.2 | BT21: =BT62 -> 0.2 | BU21: =BU62 -> 0 | BV21: # | BW21: C1MT-C1V-C1V-C1V | BX21: From CCCC in butane
B22: =B21+1 -> 20 | C22: =VEC_LMP_GMX_UniqueMap!N5 -> O2V | D22: =VEC_LMP_GMX_UniqueMap!M5 -> 15.999 | E22: =B22 -> 20 | F22: =VEC_LMP_GMX_UniqueMap!J5 -> 0.21 | G22: =VEC_LMP_GMX_UniqueMap!K5 -> 2.96 | H22: # | I22: O2-VEC/Bulk | K22: pair_coeff | L22: =E22 -> 20 | M22: =E22 -> 20 | N22: =F22 -> 0.21 | O22: =G22 -> 2.96 | P22: =2.5*O22 -> 7.4 | Q22: =H22&" "&I22 -> # O2-VEC/Bulk | U22: =U21+1 -> 20 | V22: =VEC_LMP_GMX_UniqueMap!AB7 -> 0.1529 | W22: =VEC_LMP_GMX_UniqueMap!AC7 -> 224262.4 | X22: =VEC_LMP_GMX_UniqueMap!AD7 -> C1V | Y22: =VEC_LMP_GMX_UniqueMap!AE7 -> C1V | Z22: =X22&"-"&Y22 -> C1V-C1V | AB22: bond_coeff | AC22: 20 | AD22: {=_xlfn.XLOOKUP(AG22,$Z$3:$Z$22,ROUND(0.00119502868*$W$3:$W$22,2))} -> 250 | AE22: {=_xlfn.XLOOKUP(AG22,$Z$3:$Z$22,ROUND(10*$V$3:$V$22,4))} -> 1.73 | AF22: # | AG22: NMT-SMT | AM22: =AM21+1 -> 20 | AN22: =MTFSI_LMP_GMX_UniqueMap!AU15 -> 111.1 | AO22: =MTFSI_LMP_GMX_UniqueMap!AV15 -> 527.184 | AP22: =MTFSI_LMP_GMX_UniqueMap!AW15 -> C1MT | AQ22: =MTFSI_LMP_GMX_UniqueMap!AX15 -> C1MT | AR22: =MTFSI_LMP_GMX_UniqueMap!AY15 -> C2MT | AS22: =AP22&"-"&AQ22&"-"&AR22 -> C1MT-C1MT-C2MT | AU22: angle_coeff | AV22: 20 | AW22: {=_xlfn.XLOOKUP(AZ22,$AS$3:$AS$37,ROUND(0.119502868*$AO$3:$AO$37,3))} -> 74 | AX22: {=_xlfn.XLOOKUP(AZ22,$AS$3:$AS$37,ROUND($AN$3:$AN$37,3))} -> 108.9 | AY22: # | AZ22: C1MT-SMT-O3MT | BE22: =BE21+1 -> 20 | BF22: =MTFSI_LMP_GMX_UniqueMap!BV17 -> 0 | BG22: =MTFSI_LMP_GMX_UniqueMap!BW17 -> 0 | BH22: =MTFSI_LMP_GMX_UniqueMap!BX17 -> 0 | BI22: =MTFSI_LMP_GMX_UniqueMap!BY17 -> 0 | BJ22: =MTFSI_LMP_GMX_UniqueMap!BZ17 -> 0 | BK22: =MTFSI_LMP_GMX_UniqueMap!CA17 -> 0 | BL22: =SUM(BF22:BK22) -> 0 | BM22: =MTFSI_LMP_GMX_UniqueMap!CB17&"-"&MTFSI_LMP_GMX_UniqueMap!CC17&"-"&MTFSI_LMP_GMX_UniqueMap!CD17&"-"&MTFSI_LMP_GMX_UniqueMap!CE17 -> NMT-SMT-C1MT-C1MT | BP22: dihedral_coeff | BQ22: 20 | BR22: =BR11 -> 0 | BS22: =BS11 -> 0 | BT22: =BT11 -> 0.3 | BU22: =BU11 -> 0 | BV22: # | BW22: C1MT-C1V-C1V-HV | BX22: ="Same as "&BW11 -> Same as C1MT-C1MT-C1MT-HMT
B23: =B22+1 -> 21 | C23: =MTFSI_LMP_GMX_UniqueMap!N9 -> O3MT | D23: =MTFSI_LMP_GMX_UniqueMap!M9 -> 15.999 | E23: =B23 -> 21 | F23: =MTFSI_LMP_GMX_UniqueMap!J9 -> 0.17 | G23: =MTFSI_LMP_GMX_UniqueMap!K9 -> 2.96 | H23: # | I23: O3-MT/Bulk | K23: pair_coeff | L23: =E23 -> 21 | M23: =E23 -> 21 | N23: =F23 -> 0.17 | O23: =G23 -> 2.96 | P23: =2.5*O23 -> 7.4 | Q23: =H23&" "&I23 -> # O3-MT/Bulk | AB23: bond_coeff | AC23: 21 | AD23: {=_xlfn.XLOOKUP(AG23,$Z$3:$Z$22,ROUND(0.00119502868*$W$3:$W$22,2))} -> 700 | AE23: {=_xlfn.XLOOKUP(AG23,$Z$3:$Z$22,ROUND(10*$V$3:$V$22,4))} -> 1.44 | AF23: # | AG23: O3MT-SMT | AM23: =AM22+1 -> 21 | AN23: =MTFSI_LMP_GMX_UniqueMap!AU16 -> 111.4 | AO23: =MTFSI_LMP_GMX_UniqueMap!AV16 -> 677.808 | AP23: =MTFSI_LMP_GMX_UniqueMap!AW16 -> C1MT | AQ23: =MTFSI_LMP_GMX_UniqueMap!AX16 -> C2MT | AR23: =MTFSI_LMP_GMX_UniqueMap!AY16 -> O1MT | AS23: =AP23&"-"&AQ23&"-"&AR23 -> C1MT-C2MT-O1MT | AU23: angle_coeff | AV23: 21 | AW23: =AW12 -> 63 | AX23: =AX12 -> 111.1 | AY23: # | AZ23: C1V-C1MT-C2MT | BA23: Same as C1MT-C1MT-C2MT | BE23: =BE22+1 -> 21 | BF23: =MTFSI_LMP_GMX_UniqueMap!BV18 -> 0 | BG23: =MTFSI_LMP_GMX_UniqueMap!BW18 -> 0 | BH23: =MTFSI_LMP_GMX_UniqueMap!BX18 -> 0 | BI23: =MTFSI_LMP_GMX_UniqueMap!BY18 -> 0 | BJ23: =MTFSI_LMP_GMX_UniqueMap!BZ18 -> 0 | BK23: =MTFSI_LMP_GMX_UniqueMap!CA18 -> 0 | BL23: =SUM(BF23:BK23) -> 0 | BM23: =MTFSI_LMP_GMX_UniqueMap!CB18&"-"&MTFSI_LMP_GMX_UniqueMap!CC18&"-"&MTFSI_LMP_GMX_UniqueMap!CD18&"-"&MTFSI_LMP_GMX_UniqueMap!CE18 -> NMT-SMT-C1MT-HMT | BP23: dihedral_coeff | BQ23: 21 | BR23: =BR12 -> 1.711 | BS23: =BS12 -> -0.5 | BT23: =BT12 -> 0.663 | BU23: =BU12 -> 0 | BV23: # | BW23: C1MT-C1V-C1V-O1V | BX23: ="Same as "&BW12 -> Same as C1MT-C1MT-C1MT-O1MT
B24: =B23+1 -> 22 | C24: =MTFSI_LMP_GMX_UniqueMap!N11 -> SMT | D24: =MTFSI_LMP_GMX_UniqueMap!M11 -> 32.06 | E24: =B24 -> 22 | F24: =MTFSI_LMP_GMX_UniqueMap!J11 -> 0.25 | G24: =MTFSI_LMP_GMX_UniqueMap!K11 -> 3.55 | H24: # | I24: S-MT/Bulk | K24: pair_coeff | L24: =E24 -> 22 | M24: =E24 -> 22 | N24: =F24 -> 0.25 | O24: =G24 -> 3.55 | P24: =2.5*O24 -> 8.875 | Q24: =H24&" "&I24 -> # S-MT/Bulk | AM24: =AM23+1 -> 22 | AN24: =MTFSI_LMP_GMX_UniqueMap!AU17 -> 112.7 | AO24: =MTFSI_LMP_GMX_UniqueMap!AV17 -> 488.273 | AP24: =MTFSI_LMP_GMX_UniqueMap!AW17 -> C1MT | AQ24: =MTFSI_LMP_GMX_UniqueMap!AX17 -> C1MT | AR24: =MTFSI_LMP_GMX_UniqueMap!AY17 -> C1MT | AS24: =AP24&"-"&AQ24&"-"&AR24 -> C1MT-C1MT-C1MT | AU24: angle_coeff | AV24: 22 | AW24: =AW3 -> 37.5 | AX24: =AX3 -> 110.7 | AY24: # | AZ24: C1V-C1MT-HMT | BA24: Same as HMT-C1MT-C1MT | BE24: =BE23+1 -> 22 | BF24: =MTFSI_LMP_GMX_UniqueMap!BV19 -> 0 | BG24: =MTFSI_LMP_GMX_UniqueMap!BW19 -> 0 | BH24: =MTFSI_LMP_GMX_UniqueMap!BX19 -> 0 | BI24: =MTFSI_LMP_GMX_UniqueMap!BY19 -> 0 | BJ24: =MTFSI_LMP_GMX_UniqueMap!BZ19 -> 0 | BK24: =MTFSI_LMP_GMX_UniqueMap!CA19 -> 0 | BL24: =SUM(BF24:BK24) -> 0 | BM24: =MTFSI_LMP_GMX_UniqueMap!CB19&"-"&MTFSI_LMP_GMX_UniqueMap!CC19&"-"&MTFSI_LMP_GMX_UniqueMap!CD19&"-"&MTFSI_LMP_GMX_UniqueMap!CE19 -> O2MT-C2MT-C1MT-C1MT | BP24: dihedral_coeff | BQ24: 22 | BR24: {=ROUND(0.239005736*(-2*_xlfn.XLOOKUP(BW24,$BM$3:$BM$54,ROUND($BG$3:$BG$54,5)) - 1.5*_xlfn.XLOOKUP(BW24,$BM$3:$BM$54,ROUND($BI$3:$BI$54,5))),3)} -> 4.669 | BS24: {=ROUND(0.239005736*(_xlfn.XLOOKUP(BW24,$BM$3:$BM$54,ROUND($BF$3:$BF$54,5)) + _xlfn.XLOOKUP(BW24,$BM$3:$BM$54,ROUND($BG$3:$BG$54,5)) + _xlfn.XLOOKUP(BW24,$BM$3:$BM$54,ROUND($BI$3:$BI$54,5))),3)} -> 5.124 | BT24: {=ROUND(0.239005736*(-0.5*_xlfn.XLOOKUP(BW24,$BM$3:$BM$54,ROUND($BI$3:$BI$54,5))),3)} -> 0 | BU24: {=ROUND(0.239005736*(-0.25*_xlfn.XLOOKUP(BW24,$BM$3:$BM$54,ROUND($BJ$3:$BJ$54,5))),3)} -> 0 | BV24: # | BW24: C1MT-O1MT-C2MT-C1MT | BX24: =BW24 -> C1MT-O1MT-C2MT-C1MT
AC25: Added SHAKE | AM25: =AM24+1 -> 23 | AN25: =MTFSI_LMP_GMX_UniqueMap!AU18 -> 116.57 | AO25: =MTFSI_LMP_GMX_UniqueMap!AV18 -> 504.256 | AP25: =MTFSI_LMP_GMX_UniqueMap!AW18 -> SMT | AQ25: =MTFSI_LMP_GMX_UniqueMap!AX18 -> NMT | AR25: =MTFSI_LMP_GMX_UniqueMap!AY18 -> SMT | AS25: =AP25&"-"&AQ25&"-"&AR25 -> SMT-NMT-SMT | AU25: angle_coeff | AV25: 23 | AW25: {=_xlfn.XLOOKUP(AZ25,$AS$3:$AS$37,ROUND(0.119502868*$AO$3:$AO$37,3))} -> 58.35 | AX25: {=_xlfn.XLOOKUP(AZ25,$AS$3:$AS$37,ROUND($AN$3:$AN$37,3))} -> 112.7 | AY25: # | AZ25: C1V-C1V-C1V | BE25: =BE24+1 -> 23 | BF25: =MTFSI_LMP_GMX_UniqueMap!BV20 -> 0 | BG25: =MTFSI_LMP_GMX_UniqueMap!BW20 -> 0 | BH25: =MTFSI_LMP_GMX_UniqueMap!BX20 -> 0 | BI25: =MTFSI_LMP_GMX_UniqueMap!BY20 -> 0 | BJ25: =MTFSI_LMP_GMX_UniqueMap!BZ20 -> 0 | BK25: =MTFSI_LMP_GMX_UniqueMap!CA20 -> 0 | BL25: =SUM(BF25:BK25) -> 0 | BM25: =MTFSI_LMP_GMX_UniqueMap!CB20&"-"&MTFSI_LMP_GMX_UniqueMap!CC20&"-"&MTFSI_LMP_GMX_UniqueMap!CD20&"-"&MTFSI_LMP_GMX_UniqueMap!CE20 -> O2MT-C2MT-C1MT-HMT | BP25: dihedral_coeff | BQ25: 23 | BR25: =BR62 -> 1.3 | BS25: =BS62 -> -0.2 | BT25: =BT62 -> 0.2 | BU25: =BU62 -> 0 | BV25: # | BW25: C1V-C1MT-C1MT-C1V | BX25: From CCCC in butane
AM26: =AM25+1 -> 24 | AN26: =MTFSI_LMP_GMX_UniqueMap!AU19 -> 116.9 | AO26: =MTFSI_LMP_GMX_UniqueMap!AV19 -> 694.544 | AP26: =MTFSI_LMP_GMX_UniqueMap!AW19 -> C2MT | AQ26: =MTFSI_LMP_GMX_UniqueMap!AX19 -> O1MT | AR26: =MTFSI_LMP_GMX_UniqueMap!AY19 -> C1MT | AS26: =AP26&"-"&AQ26&"-"&AR26 -> C2MT-O1MT-C1MT | AU26: angle_coeff | AV26: 24 | AW26: {=_xlfn.XLOOKUP(AZ26,$AS$3:$AS$37,ROUND(0.119502868*$AO$3:$AO$37,3))} -> 37.5 | AX26: {=_xlfn.XLOOKUP(AZ26,$AS$3:$AS$37,ROUND($AN$3:$AN$37,3))} -> 110.7 | AY26: # | AZ26: HV-C1V-C1V | BE26: =BE25+1 -> 24 | BF26: =MTFSI_LMP_GMX_UniqueMap!BV21 -> -1.157 | BG26: =MTFSI_LMP_GMX_UniqueMap!BW21 -> -3.471 | BH26: =MTFSI_LMP_GMX_UniqueMap!BX21 -> 0 | BI26: =MTFSI_LMP_GMX_UniqueMap!BY21 -> 4.628 | BJ26: =MTFSI_LMP_GMX_UniqueMap!BZ21 -> 0 | BK26: =MTFSI_LMP_GMX_UniqueMap!CA21 -> 0 | BL26: =SUM(BF26:BK26) -> 0 | BM26: =MTFSI_LMP_GMX_UniqueMap!CB21&"-"&MTFSI_LMP_GMX_UniqueMap!CC21&"-"&MTFSI_LMP_GMX_UniqueMap!CD21&"-"&MTFSI_LMP_GMX_UniqueMap!CE21 -> O1MT-C2MT-C1MT-C1MT | BP26: dihedral_coeff | BQ26: 24 | BR26: =BR63 -> -2.06 | BS26: =BS63 -> -0.313 | BT26: =BT63 -> 0.315 | BU26: =BU63 -> 0 | BV26: # | BW26: C1V-C1MT-C1MT-C2MT | BX26: From CCCC in butyric acid
AM27: =AM26+1 -> 25 | AN27: =MTFSI_LMP_GMX_UniqueMap!AU20 -> 119 | AO27: =MTFSI_LMP_GMX_UniqueMap!AV20 -> 870.272 | AP27: =MTFSI_LMP_GMX_UniqueMap!AW20 -> O3MT | AQ27: =MTFSI_LMP_GMX_UniqueMap!AX20 -> SMT | AR27: =MTFSI_LMP_GMX_UniqueMap!AY20 -> O3MT | AS27: =AP27&"-"&AQ27&"-"&AR27 -> O3MT-SMT-O3MT | AU27: angle_coeff | AV27: 25 | AW27: {=_xlfn.XLOOKUP(AZ27,$AS$3:$AS$37,ROUND(0.119502868*$AO$3:$AO$37,3))} -> 50 | AX27: {=_xlfn.XLOOKUP(AZ27,$AS$3:$AS$37,ROUND($AN$3:$AN$37,3))} -> 109.5 | AY27: # | AZ27: C1V-C1V-O1V | BE27: =BE26+1 -> 25 | BF27: =MTFSI_LMP_GMX_UniqueMap!BV22 -> 0.276 | BG27: =MTFSI_LMP_GMX_UniqueMap!BW22 -> 0.828 | BH27: =MTFSI_LMP_GMX_UniqueMap!BX22 -> 0 | BI27: =MTFSI_LMP_GMX_UniqueMap!BY22 -> -1.105 | BJ27: =MTFSI_LMP_GMX_UniqueMap!BZ22 -> 0 | BK27: =MTFSI_LMP_GMX_UniqueMap!CA22 -> 0 | BL27: =SUM(BF27:BK27) -> -0.001 | BM27: =MTFSI_LMP_GMX_UniqueMap!CB22&"-"&MTFSI_LMP_GMX_UniqueMap!CC22&"-"&MTFSI_LMP_GMX_UniqueMap!CD22&"-"&MTFSI_LMP_GMX_UniqueMap!CE22 -> O1MT-C2MT-C1MT-HMT | BP27: dihedral_coeff | BQ27: 25 | BR27: =BR11 -> 0 | BS27: =BS11 -> 0 | BT27: =BT11 -> 0.3 | BU27: =BU11 -> 0 | BV27: # | BW27: C1V-C1MT-C1MT-HMT | BX27: ="Same as "&BW11 -> Same as C1MT-C1MT-C1MT-HMT
F28: NOTE: In most cases, types 23 and 5 are identical and hence type 23 is omitted. Check each time | AM28: =AM27+1 -> 26 | AN28: =MTFSI_LMP_GMX_UniqueMap!AU21 -> 120.4 | AO28: =MTFSI_LMP_GMX_UniqueMap!AV21 -> 669.44 | AP28: =MTFSI_LMP_GMX_UniqueMap!AW21 -> C1MT | AQ28: =MTFSI_LMP_GMX_UniqueMap!AX21 -> C2MT | AR28: =MTFSI_LMP_GMX_UniqueMap!AY21 -> O2MT | AS28: =AP28&"-"&AQ28&"-"&AR28 -> C1MT-C2MT-O2MT | AU28: angle_coeff | AV28: 26 | AW28: {=_xlfn.XLOOKUP(AZ28,$AS$3:$AS$37,ROUND(0.119502868*$AO$3:$AO$37,3))} -> 83 | AX28: {=_xlfn.XLOOKUP(AZ28,$AS$3:$AS$37,ROUND($AN$3:$AN$37,3))} -> 116.9 | AY28: # | AZ28: C1V-O1V-C2V | BE28: =BE27+1 -> 26 | BF28: =MTFSI_LMP_GMX_UniqueMap!BV23 -> 0 | BG28: =MTFSI_LMP_GMX_UniqueMap!BW23 -> 0 | BH28: =MTFSI_LMP_GMX_UniqueMap!BX23 -> 0 | BI28: =MTFSI_LMP_GMX_UniqueMap!BY23 -> 0 | BJ28: =MTFSI_LMP_GMX_UniqueMap!BZ23 -> 0 | BK28: =MTFSI_LMP_GMX_UniqueMap!CA23 -> 0 | BL28: =SUM(BF28:BK28) -> 0 | BM28: =MTFSI_LMP_GMX_UniqueMap!CB23&"-"&MTFSI_LMP_GMX_UniqueMap!CC23&"-"&MTFSI_LMP_GMX_UniqueMap!CD23&"-"&MTFSI_LMP_GMX_UniqueMap!CE23 -> O3MT-SMT-C1MT-C1MT | BP28: dihedral_coeff | BQ28: 26 | BR28: =BR16 -> 0 | BS28: =BS16 -> 0 | BT28: =BT16 -> -0.553 | BU28: =BU16 -> 0 | BV28: # | BW28: C1V-C1MT-C2MT-O1MT | BX28: ="Same as "&BW16 -> Same as O1MT-C2MT-C1MT-C1MT
AM29: =AM28+1 -> 27 | AN29: =MTFSI_LMP_GMX_UniqueMap!AU22 -> 123.4 | AO29: =MTFSI_LMP_GMX_UniqueMap!AV22 -> 694.544 | AP29: =MTFSI_LMP_GMX_UniqueMap!AW22 -> O1MT | AQ29: =MTFSI_LMP_GMX_UniqueMap!AX22 -> C2MT | AR29: =MTFSI_LMP_GMX_UniqueMap!AY22 -> O2MT | AS29: =AP29&"-"&AQ29&"-"&AR29 -> O1MT-C2MT-O2MT | AU29: angle_coeff | AV29: 27 | AW29: {=_xlfn.XLOOKUP(AZ29,$AS$3:$AS$37,ROUND(0.119502868*$AO$3:$AO$37,3))} -> 77 | AX29: {=_xlfn.XLOOKUP(AZ29,$AS$3:$AS$37,ROUND($AN$3:$AN$37,3))} -> 109.1 | AY29: # | AZ29: FMT-C1MT-FMT | BE29: =BE28+1 -> 27 | BF29: =MTFSI_LMP_GMX_UniqueMap!BV24 -> 0.732 | BG29: =MTFSI_LMP_GMX_UniqueMap!BW24 -> 2.197 | BH29: =MTFSI_LMP_GMX_UniqueMap!BX24 -> 0 | BI29: =MTFSI_LMP_GMX_UniqueMap!BY24 -> -2.929 | BJ29: =MTFSI_LMP_GMX_UniqueMap!BZ24 -> 0 | BK29: =MTFSI_LMP_GMX_UniqueMap!CA24 -> 0 | BL29: =SUM(BF29:BK29) -> 4.4408921e-16 | BM29: =MTFSI_LMP_GMX_UniqueMap!CB24&"-"&MTFSI_LMP_GMX_UniqueMap!CC24&"-"&MTFSI_LMP_GMX_UniqueMap!CD24&"-"&MTFSI_LMP_GMX_UniqueMap!CE24 -> O3MT-SMT-C1MT-HMT | BP29: dihedral_coeff | BQ29: 27 | BR29: =BR17 -> 0 | BS29: =BS17 -> 0 | BT29: =BT17 -> 0 | BU29: =BU17 -> 0 | BV29: # | BW29: C1V-C1MT-C2MT-O2MT | BX29: ="Same as "&BW17 -> Same as O2MT-C2MT-C1MT-C1MT
B30: 23 | C30: =C7 -> LP | D30: =D7 -> 6.941 | E30: =B30 -> 23 | F30: =F7 -> 0.4 | G30: =G7 -> 1.4 | H30: =H7 -> # | I30: Li-LP/Bulk (Table1: https://pubs.acs.org/doi/10.1021/acs.jpcb.3c05591, Wu-Wick) | AM30: =AM29+1 -> 28 | AN30: =VEC_LMP_GMX_UniqueMap!AU3 -> 107.8 | AO30: =VEC_LMP_GMX_UniqueMap!AV3 -> 276.144 | AP30: =VEC_LMP_GMX_UniqueMap!AW3 -> HV | AQ30: =VEC_LMP_GMX_UniqueMap!AX3 -> C1V | AR30: =VEC_LMP_GMX_UniqueMap!AY3 -> HV | AS30: =AP30&"-"&AQ30&"-"&AR30 -> HV-C1V-HV | AU30: angle_coeff | AV30: 28 | AW30: {=_xlfn.XLOOKUP(AZ30,$AS$3:$AS$37,ROUND(0.119502868*$AO$3:$AO$37,3))} -> 50 | AX30: {=_xlfn.XLOOKUP(AZ30,$AS$3:$AS$37,ROUND($AN$3:$AN$37,3))} -> 109.5 | AY30: # | AZ30: SMT-C1MT-FMT | BE30: =BE29+1 -> 28 | BF30: =MTFSI_LMP_GMX_UniqueMap!BV25 -> 0 | BG30: =MTFSI_LMP_GMX_UniqueMap!BW25 -> 0 | BH30: =MTFSI_LMP_GMX_UniqueMap!BX25 -> 0 | BI30: =MTFSI_LMP_GMX_UniqueMap!BY25 -> 0 | BJ30: =MTFSI_LMP_GMX_UniqueMap!BZ25 -> 0 | BK30: =MTFSI_LMP_GMX_UniqueMap!CA25 -> 0 | BL30: =SUM(BF30:BK30) -> 0 | BM30: =MTFSI_LMP_GMX_UniqueMap!CB25&"-"&MTFSI_LMP_GMX_UniqueMap!CC25&"-"&MTFSI_LMP_GMX_UniqueMap!CD25&"-"&MTFSI_LMP_GMX_UniqueMap!CE25 -> O3MT-SMT-NMT-SMT | BP30: dihedral_coeff | BQ30: 28 | BR30: {=ROUND(0.239005736*(-2*_xlfn.XLOOKUP(BW30,$BM$3:$BM$54,ROUND($BG$3:$BG$54,5)) - 1.5*_xlfn.XLOOKUP(BW30,$BM$3:$BM$54,ROUND($BI$3:$BI$54,5))),3)} -> 1.3 | BS30: {=ROUND(0.239005736*(_xlfn.XLOOKUP(BW30,$BM$3:$BM$54,ROUND($BF$3:$BF$54,5)) + _xlfn.XLOOKUP(BW30,$BM$3:$BM$54,ROUND($BG$3:$BG$54,5)) + _xlfn.XLOOKUP(BW30,$BM$3:$BM$54,ROUND($BI$3:$BI$54,5))),3)} -> -0.2 | BT30: {=ROUND(0.239005736*(-0.5*_xlfn.XLOOKUP(BW30,$BM$3:$BM$54,ROUND($BI$3:$BI$54,5))),3)} -> 0.2 | BU30: {=ROUND(0.239005736*(-0.25*_xlfn.XLOOKUP(BW30,$BM$3:$BM$54,ROUND($BJ$3:$BJ$54,5))),3)} -> 0 | BV30: # | BW30: C1V-C1V-C1V-C1V
